Workbook
Name cfg_labels_ft_label: Config!$R$6
Name cfg_labels_ft_name: Config!$R$6
Name cfg_labels_imported: Config!$R$5
Name cfg_projectKey: Config!$R$4
Name cfg_type_comment: Config!$M$4
Name cfg_type_note: Config!$M$6
Name cfg_type_skip: Config!$M$5
Name cfg_type_workitem: Config!$M$7

Sheet Dataset
A1: Priority | B1: IssueType | C1: Summary | D1: Issue Key | E1: Description | F1: FixVersion | G1: Assignee.Name | H1: Component | I1: Sprint Name | J1: CF Number | K1: CF Plain Text | L1: Estimate | M1: Issue ID | N1: Parent | O1: Epic Link | P1: Epic Name | Q1: Child-Issue | R1: Child-Issue1 | S1: Child-Issue2 | T1: Labels | U1: Labels1 | V1: Labels2 | W1: Labels3 | X1: Labels4 | Y1: Labels5 | Z1: Labels6 | AA1: Labels7 | AB1: Labels8 | AC1: Labels9 | AD1: Labels10 | AE1: Sprint | AF1: Labels0001 | AG1: Labels0002 | AH1: Assignee | AI1: Project Key | AJ1: OrigEst | AK1: RowType | AL1: Note
B2: Note | C2: FORMULA HOLDER | E2: DO NOT DELETE OR CLEAR THIS ROW | L2: 1w 2d 3h | P2: =IF(JiraDataset[[#This Row],[IssueType]]="Epic",JiraDataset[[#This Row],[Summary]],"") | AE2: =IF(JiraDataset[[#This Row],[RowType]]=cfg_type_skip,"",IFERROR(VLOOKUP(JiraDataset[[#This Row],[Sprint Name]], Config!$D$4:$E$9, 2, FALSE), "")) | AF2: =IF(JiraDataset[[#This Row],[RowType]]=cfg_type_skip,"",_xlfn.XLOOKUP("Creation Marker", CfgAutofieldValues[Name], CfgAutofieldValues[Value])) | AG2: =IF(JiraDataset[[#This Row],[RowType]]=cfg_type_skip,"",_xlfn.XLOOKUP("Feature Pod Label", CfgAutofieldValues[Name], CfgAutofieldValues[Value])) | AH2: =IF(JiraDataset[[#This Row],[RowType]]=cfg_type_skip,"",IFERROR(VLOOKUP(JiraDataset[[#This Row],[Assignee.Name]], Config!$A$4:$B$24, 2, FALSE), "")) | AI2: =IF(JiraDataset[[#This Row],[RowType]]=cfg_type_skip,"",_xlfn.XLOOKUP("jira.project.key", CfgAutofieldValues[Name], CfgAutofieldValues[Value])) | AJ2: {=IF( JiraDataset[[#This Row],[RowType]]=cfg_type_skip, "", _xlfn.LET( _xlpm.p, _xlfn.TEXTSPLIT(JiraDataset[[#This Row],[Estimate]], " "), _xlpm.getVal, _xlfn.LAMBDA(_xlpm.u, IFERROR(VALUE(LEFT(_xlfn._xlws.FILTER(_xlpm.p, RIGHT(_xlpm.p,1)=_xlpm.u), LEN(_xlfn._xlws.FILTER(_xlpm.p, RIGHT(_xlpm.p,1)=_xlpm.u))-1)), 0)), _xlpm.w, _xlpm.getVal("w"), _xlpm.d, _xlpm.getVal("d"), _xlpm.h, _xlpm.getVal("h"), _xlpm.m, _xlpm.getVal("m"), _xlpm.seconds, _xlpm.w*144000 + _xlpm.d*28800 + _xlpm.h*3600 + _xlpm.m*60, IF(_xlpm.seconds=0, "", _xlpm.seconds*60) ) )} | AK2: {=IFERROR( _xlfn.IFS( JiraDataset[[#This Row],[IssueType]] = cfg_type_comment,"SKIP", JiraDataset[[#This Row],[IssueType]] = cfg_type_skip,"SKIP", JiraDataset[[#This Row],[IssueType]] = cfg_type_note,"SKIP" ), cfg_type_workitem )} -> SKIP
A3: High | B3: initiative | C3: Digital Transformation Program | E3: Top-level initiative coordinating cross-domain work | F3: JITTP Version 1 | G3: joe.grunt | J3: 1 | K3: abc | L3: 2w | M3: 1 | P3: =IF(JiraDataset[[#This Row],[IssueType]]="Epic",JiraDataset[[#This Row],[Summary]],"") | AE3: =IF(JiraDataset[[#This Row],[RowType]]=cfg_type_skip,"",IFERROR(VLOOKUP(JiraDataset[[#This Row],[Sprint Name]], Config!$D$4:$E$9, 2, FALSE), "")) | AF3: =IF(JiraDataset[[#This Row],[RowType]]=cfg_type_skip,"",_xlfn.XLOOKUP("Creation Marker", CfgAutofieldValues[Name], CfgAutofieldValues[Value])) -> jt-imported | AG3: =IF(JiraDataset[[#This Row],[RowType]]=cfg_type_skip,"",_xlfn.XLOOKUP("Feature Pod Label", CfgAutofieldValues[Name], CfgAutofieldValues[Value])) -> ft-group-1 | AH3: =IF(JiraDataset[[#This Row],[RowType]]=cfg_type_skip,"",IFERROR(VLOOKUP(JiraDataset[[#This Row],[Assignee.Name]], Config!$A$4:$B$24, 2, FALSE), "")) -> someID | AI3: =IF(JiraDataset[[#This Row],[RowType]]=cfg_type_skip,"",_xlfn.XLOOKUP("jira.project.key", CfgAutofieldValues[Name], CfgAutofieldValues[Value])) -> PRJ_KEY | AJ3: {=IF( JiraDataset[[#This Row],[RowType]]=cfg_type_skip, "", _xlfn.LET( _xlpm.p, _xlfn.TEXTSPLIT(JiraDataset[[#This Row],[Estimate]], " "), _xlpm.getVal, _xlfn.LAMBDA(_xlpm.u, IFERROR(VALUE(LEFT(_xlfn._xlws.FILTER(_xlpm.p, RIGHT(_xlpm.p,1)=_xlpm.u), LEN(_xlfn._xlws.FILTER(_xlpm.p, RIGHT(_xlpm.p,1)=_xlpm.u))-1)), 0)), _xlpm.w, _xlpm.getVal("w"), _xlpm.d, _xlpm.getVal("d"), _xlpm.h, _xlpm.getVal("h"), _xlpm.m, _xlpm.getVal("m"), _xlpm.seconds, _xlpm.w*144000 + _xlpm.d*28800 + _xlpm.h*3600 + _xlpm.m*60, IF(_xlpm.seconds=0, "", _xlpm.seconds*60) ) )} -> 17280000 | AK3: {=IFERROR( _xlfn.IFS( JiraDataset[[#This Row],[IssueType]] = cfg_type_comment,"SKIP", JiraDataset[[#This Row],[IssueType]] = cfg_type_skip,"SKIP", JiraDataset[[#This Row],[IssueType]] = cfg_type_note,"SKIP" ), cfg_type_workitem )} -> WorkItem
A4: Medium | B4: epic | C4: Customer Onboarding Revamp | E4: Improve first-time user experience and activation | F4: JITTP Version 1 | G4: john.doe | H4: Product | J4: 1 | K4: abc | L4: 1w | M4: 2 | N4: 1 | P4: =IF(JiraDataset[[#This Row],[IssueType]]="Epic",JiraDataset[[#This Row],[Summary]],"") -> Customer Onboarding Revamp | AE4: =IF(JiraDataset[[#This Row],[RowType]]=cfg_type_skip,"",IFERROR(VLOOKUP(JiraDataset[[#This Row],[Sprint Name]], Config!$D$4:$E$9, 2, FALSE), "")) | AF4: =IF(JiraDataset[[#This Row],[RowType]]=cfg_type_skip,"",_xlfn.XLOOKUP("Creation Marker", CfgAutofieldValues[Name], CfgAutofieldValues[Value])) -> jt-imported | AG4: =IF(JiraDataset[[#This Row],[RowType]]=cfg_type_skip,"",_xlfn.XLOOKUP("Feature Pod Label", CfgAutofieldValues[Name], CfgAutofieldValues[Value])) -> ft-group-1 | AH4: =IF(JiraDataset[[#This Row],[RowType]]=cfg_type_skip,"",IFERROR(VLOOKUP(JiraDataset[[#This Row],[Assignee.Name]], Config!$A$4:$B$24, 2, FALSE), "")) -> someID | AI4: =IF(JiraDataset[[#This Row],[RowType]]=cfg_type_skip,"",_xlfn.XLOOKUP("jira.project.key", CfgAutofieldValues[Name], CfgAutofieldValues[Value])) -> PRJ_KEY | AJ4: {=IF( JiraDataset[[#This Row],[RowType]]=cfg_type_skip, "", _xlfn.LET( _xlpm.p, _xlfn.TEXTSPLIT(JiraDataset[[#This Row],[Estimate]], " "), _xlpm.getVal, _xlfn.LAMBDA(_xlpm.u, IFERROR(VALUE(LEFT(_xlfn._xlws.FILTER(_xlpm.p, RIGHT(_xlpm.p,1)=_xlpm.u), LEN(_xlfn._xlws.FILTER(_xlpm.p, RIGHT(_xlpm.p,1)=_xlpm.u))-1)), 0)), _xlpm.w, _xlpm.getVal("w"), _xlpm.d, _xlpm.getVal("d"), _xlpm.h, _xlpm.getVal("h"), _xlpm.m, _xlpm.getVal("m"), _xlpm.seconds, _xlpm.w*144000 + _xlpm.d*28800 + _xlpm.h*3600 + _xlpm.m*60, IF(_xlpm.seconds=0, "", _xlpm.seconds*60) ) )} -> 8640000 | AK4: {=IFERROR( _xlfn.IFS( JiraDataset[[#This Row],[IssueType]] = cfg_type_comment,"SKIP", JiraDataset[[#This Row],[IssueType]] = cfg_type_skip,"SKIP", JiraDataset[[#This Row],[IssueType]] = cfg_type_note,"SKIP" ), cfg_type_workitem )} -> WorkItem
A5: Highest | B5: story | C5: Design Welcome Flow | E5: Create wireframes and copy for welcome steps | F5: =Config!$G$4 -> JITTP Version 1 | G5: jane.smith | H5: UX | J5: 1 | K5: abc | L5: 3d | M5: 3 | N5: 2 | P5: =IF(JiraDataset[[#This Row],[IssueType]]="Epic",JiraDataset[[#This Row],[Summary]],"") | AE5: =IF(JiraDataset[[#This Row],[RowType]]=cfg_type_skip,"",IFERROR(VLOOKUP(JiraDataset[[#This Row],[Sprint Name]], Config!$D$4:$E$9, 2, FALSE), "")) | AF5: =IF(JiraDataset[[#This Row],[RowType]]=cfg_type_skip,"",_xlfn.XLOOKUP("Creation Marker", CfgAutofieldValues[Name], CfgAutofieldValues[Value])) -> jt-imported | AG5: =IF(JiraDataset[[#This Row],[RowType]]=cfg_type_skip,"",_xlfn.XLOOKUP("Feature Pod Label", CfgAutofieldValues[Name], CfgAutofieldValues[Value])) -> ft-group-1 | AH5: =IF(JiraDataset[[#This Row],[RowType]]=cfg_type_skip,"",IFERROR(VLOOKUP(JiraDataset[[#This Row],[Assignee.Name]], Config!$A$4:$B$24, 2, FALSE), "")) -> someID | AI5: =IF(JiraDataset[[#This Row],[RowType]]=cfg_type_skip,"",_xlfn.XLOOKUP("jira.project.key", CfgAutofieldValues[Name], CfgAutofieldValues[Value])) -> PRJ_KEY | AJ5: {=IF( JiraDataset[[#This Row],[RowType]]=cfg_type_skip, "", _xlfn.LET( _xlpm.p, _xlfn.TEXTSPLIT(JiraDataset[[#This Row],[Estimate]], " "), _xlpm.getVal, _xlfn.LAMBDA(_xlpm.u, IFERROR(VALUE(LEFT(_xlfn._xlws.FILTER(_xlpm.p, RIGHT(_xlpm.p,1)=_xlpm.u), LEN(_xlfn._xlws.FILTER(_xlpm.p, RIGHT(_xlpm.p,1)=_xlpm.u))-1)), 0)), _xlpm.w, _xlpm.getVal("w"), _xlpm.d, _xlpm.getVal("d"), _xlpm.h, _xlpm.getVal("h"), _xlpm.m, _xlpm.getVal("m"), _xlpm.seconds, _xlpm.w*144000 + _xlpm.d*28800 + _xlpm.h*3600 + _xlpm.m*60, IF(_xlpm.seconds=0, "", _xlpm.seconds*60) ) )} -> 5184000 | AK5: {=IFERROR( _xlfn.IFS( JiraDataset[[#This Row],[IssueType]] = cfg_type_comment,"SKIP", JiraDataset[[#This Row],[IssueType]] = cfg_type_skip,"SKIP", JiraDataset[[#This Row],[IssueType]] = cfg_type_note,"SKIP" ), cfg_type_workitem )} -> WorkItem
A6: High | B6: task | C6: Implement Welcome Screens | E6: Build front-end for multi-step welcome | F6: =Config!$G$4 -> JITTP Version 1 | G6: Alice A | H6: Frontend | J6: 1 | K6: abc | L6: 4d | M6: 4 | N6: 2 | P6: =IF(JiraDataset[[#This Row],[IssueType]]="Epic",JiraDataset[[#This Row],[Summary]],"") | AE6: =IF(JiraDataset[[#This Row],[RowType]]=cfg_type_skip,"",IFERROR(VLOOKUP(JiraDataset[[#This Row],[Sprint Name]], Config!$D$4:$E$9, 2, FALSE), "")) | AF6: =IF(JiraDataset[[#This Row],[RowType]]=cfg_type_skip,"",_xlfn.XLOOKUP("Creation Marker", CfgAutofieldValues[Name], CfgAutofieldValues[Value])) -> jt-imported | AG6: =IF(JiraDataset[[#This Row],[RowType]]=cfg_type_skip,"",_xlfn.XLOOKUP("Feature Pod Label", CfgAutofieldValues[Name], CfgAutofieldValues[Value])) -> ft-group-1 | AH6: =IF(JiraDataset[[#This Row],[RowType]]=cfg_type_skip,"",IFERROR(VLOOKUP(JiraDataset[[#This Row],[Assignee.Name]], Config!$A$4:$B$24, 2, FALSE), "")) -> someID | AI6: =IF(JiraDataset[[#This Row],[RowType]]=cfg_type_skip,"",_xlfn.XLOOKUP("jira.project.key", CfgAutofieldValues[Name], CfgAutofieldValues[Value])) -> PRJ_KEY | AJ6: {=IF( JiraDataset[[#This Row],[RowType]]=cfg_type_skip, "", _xlfn.LET( _xlpm.p, _xlfn.TEXTSPLIT(JiraDataset[[#This Row],[Estimate]], " "), _xlpm.getVal, _xlfn.LAMBDA(_xlpm.u, IFERROR(VALUE(LEFT(_xlfn._xlws.FILTER(_xlpm.p, RIGHT(_xlpm.p,1)=_xlpm.u), LEN(_xlfn._xlws.FILTER(_xlpm.p, RIGHT(_xlpm.p,1)=_xlpm.u))-1)), 0)), _xlpm.w, _xlpm.getVal("w"), _xlpm.d, _xlpm.getVal("d"), _xlpm.h, _xlpm.getVal("h"), _xlpm.m, _xlpm.getVal("m"), _xlpm.seconds, _xlpm.w*144000 + _xlpm.d*28800 + _xlpm.h*3600 + _xlpm.m*60, IF(_xlpm.seconds=0, "", _xlpm.seconds*60) ) )} -> 6912000 | AK6: {=IFERROR( _xlfn.IFS( JiraDataset[[#This Row],[IssueType]] = cfg_type_comment,"SKIP", JiraDataset[[#This Row],[IssueType]] = cfg_type_skip,"SKIP", JiraDataset[[#This Row],[IssueType]] = cfg_type_note,"SKIP" ), cfg_type_workitem )} -> WorkItem
A7: Low | B7: bug | C7: Fix Broken Skip Button | E7: Skip button unresponsive on step 2 | F7: =Config!$G$4 -> JITTP Version 1 | G7: Bob B | H7: Frontend | J7: 1 | K7: abc | L7: 6h | M7: 5 | N7: 2 | P7: =IF(JiraDataset[[#This Row],[IssueType]]="Epic",JiraDataset[[#This Row],[Summary]],"") | AE7: =IF(JiraDataset[[#This Row],[RowType]]=cfg_type_skip,"",IFERROR(VLOOKUP(JiraDataset[[#This Row],[Sprint Name]], Config!$D$4:$E$9, 2, FALSE), "")) | AF7: =IF(JiraDataset[[#This Row],[RowType]]=cfg_type_skip,"",_xlfn.XLOOKUP("Creation Marker", CfgAutofieldValues[Name], CfgAutofieldValues[Value])) -> jt-imported | AG7: =IF(JiraDataset[[#This Row],[RowType]]=cfg_type_skip,"",_xlfn.XLOOKUP("Feature Pod Label", CfgAutofieldValues[Name], CfgAutofieldValues[Value])) -> ft-group-1 | AH7: =IF(JiraDataset[[#This Row],[RowType]]=cfg_type_skip,"",IFERROR(VLOOKUP(JiraDataset[[#This Row],[Assignee.Name]], Config!$A$4:$B$24, 2, FALSE), "")) -> someID | AI7: =IF(JiraDataset[[#This Row],[RowType]]=cfg_type_skip,"",_xlfn.XLOOKUP("jira.project.key", CfgAutofieldValues[Name], CfgAutofieldValues[Value])) -> PRJ_KEY | AJ7: {=IF( JiraDataset[[#This Row],[RowType]]=cfg_type_skip, "", _xlfn.LET( _xlpm.p, _xlfn.TEXTSPLIT(JiraDataset[[#This Row],[Estimate]], " "), _xlpm.getVal, _xlfn.LAMBDA(_xlpm.u, IFERROR(VALUE(LEFT(_xlfn._xlws.FILTER(_xlpm.p, RIGHT(_xlpm.p,1)=_xlpm.u), LEN(_xlfn._xlws.FILTER(_xlpm.p, RIGHT(_xlpm.p,1)=_xlpm.u))-1)), 0)), _xlpm.w, _xlpm.getVal("w"), _xlpm.d, _xlpm.getVal("d"), _xlpm.h, _xlpm.getVal("h"), _xlpm.m, _xlpm.getVal("m"), _xlpm.seconds, _xlpm.w*144000 + _xlpm.d*28800 + _xlpm.h*3600 + _xlpm.m*60, IF(_xlpm.seconds=0, "", _xlpm.seconds*60) ) )} -> 1296000 | AK7: {=IFERROR( _xlfn.IFS( JiraDataset[[#This Row],[IssueType]] = cfg_type_comment,"SKIP", JiraDataset[[#This Row],[IssueType]] = cfg_type_skip,"SKIP", JiraDataset[[#This Row],[IssueType]] = cfg_type_note,"SKIP" ), cfg_type_workitem )} -> WorkItem
A8: Lowest | B8: sub-task | C8: Unit Tests: Welcome Flow | E8: Cover edge cases for welcome logic | F8: =Config!$G$4 -> JITTP Version 1 | G8: joe.grunt | H8: Testing | J8: 1 | K8: abc | L8: 1d | M8: 6 | N8: 3 | P8: =IF(JiraDataset[[#This Row],[IssueType]]="Epic",JiraDataset[[#This Row],[Summary]],"") | AE8: =IF(JiraDataset[[#This Row],[RowType]]=cfg_type_skip,"",IFERROR(VLOOKUP(JiraDataset[[#This Row],[Sprint Name]], Config!$D$4:$E$9, 2, FALSE), "")) | AF8: =IF(JiraDataset[[#This Row],[RowType]]=cfg_type_skip,"",_xlfn.XLOOKUP("Creation Marker", CfgAutofieldValues[Name], CfgAutofieldValues[Value])) -> jt-imported | AG8: =IF(JiraDataset[[#This Row],[RowType]]=cfg_type_skip,"",_xlfn.XLOOKUP("Feature Pod Label", CfgAutofieldValues[Name], CfgAutofieldValues[Value])) -> ft-group-1 | AH8: =IF(JiraDataset[[#This Row],[RowType]]=cfg_type_skip,"",IFERROR(VLOOKUP(JiraDataset[[#This Row],[Assignee.Name]], Config!$A$4:$B$24, 2, FALSE), "")) -> someID | AI8: =IF(JiraDataset[[#This Row],[RowType]]=cfg_type_skip,"",_xlfn.XLOOKUP("jira.project.key", CfgAutofieldValues[Name], CfgAutofieldValues[Value])) -> PRJ_KEY | AJ8: {=IF( JiraDataset[[#This Row],[RowType]]=cfg_type_skip, "", _xlfn.LET( _xlpm.p, _xlfn.TEXTSPLIT(JiraDataset[[#This Row],[Estimate]], " "), _xlpm.getVal, _xlfn.LAMBDA(_xlpm.u, IFERROR(VALUE(LEFT(_xlfn._xlws.FILTER(_xlpm.p, RIGHT(_xlpm.p,1)=_xlpm.u), LEN(_xlfn._xlws.FILTER(_xlpm.p, RIGHT(_xlpm.p,1)=_xlpm.u))-1)), 0)), _xlpm.w, _xlpm.getVal("w"), _xlpm.d, _xlpm.getVal("d"), _xlpm.h, _xlpm.getVal("h"), _xlpm.m, _xlpm.getVal("m"), _xlpm.seconds, _xlpm.w*144000 + _xlpm.d*28800 + _xlpm.h*3600 + _xlpm.m*60, IF(_xlpm.seconds=0, "", _xlpm.seconds*60) ) )} -> 1728000 | AK8: {=IFERROR( _xlfn.IFS( JiraDataset[[#This Row],[IssueType]] = cfg_type_comment,"SKIP", JiraDataset[[#This Row],[IssueType]] = cfg_type_skip,"SKIP", JiraDataset[[#This Row],[IssueType]] = cfg_type_note,"SKIP" ), cfg_type_workitem )} -> WorkItem
A9: Highest | B9: Task | C9: Authentication & Accounts | E9: Modernize auth | F9: =Config!$G$4 -> JITTP Version 1 | G9: jane.smith | H9: Security | J9: 1 | K9: abc | L9: 1.1 | M9: 7 | N9: 2 | P9: =IF(JiraDataset[[#This Row],[IssueType]]="Epic",JiraDataset[[#This Row],[Summary]],"") | AE9: =IF(JiraDataset[[#This Row],[RowType]]=cfg_type_skip,"",IFERROR(VLOOKUP(JiraDataset[[#This Row],[Sprint Name]], Config!$D$4:$E$9, 2, FALSE), "")) | AF9: =IF(JiraDataset[[#This Row],[RowType]]=cfg_type_skip,"",_xlfn.XLOOKUP("Creation Marker", CfgAutofieldValues[Name], CfgAutofieldValues[Value])) -> jt-imported | AG9: =IF(JiraDataset[[#This Row],[RowType]]=cfg_type_skip,"",_xlfn.XLOOKUP("Feature Pod Label", CfgAutofieldValues[Name], CfgAutofieldValues[Value])) -> ft-group-1 | AH9: =IF(JiraDataset[[#This Row],[RowType]]=cfg_type_skip,"",IFERROR(VLOOKUP(JiraDataset[[#This Row],[Assignee.Name]], Config!$A$4:$B$24, 2, FALSE), "")) -> someID | AI9: =IF(JiraDataset[[#This Row],[RowType]]=cfg_type_skip,"",_xlfn.XLOOKUP("jira.project.key", CfgAutofieldValues[Name], CfgAutofieldValues[Value])) -> PRJ_KEY | AJ9: {=IF( JiraDataset[[#This Row],[RowType]]=cfg_type_skip, "", _xlfn.LET( _xlpm.p, _xlfn.TEXTSPLIT(JiraDataset[[#This Row],[Estimate]], " "), _xlpm.getVal, _xlfn.LAMBDA(_xlpm.u, IFERROR(VALUE(LEFT(_xlfn._xlws.FILTER(_xlpm.p, RIGHT(_xlpm.p,1)=_xlpm.u), LEN(_xlfn._xlws.FILTER(_xlpm.p, RIGHT(_xlpm.p,1)=_xlpm.u))-1)), 0)), _xlpm.w, _xlpm.getVal("w"), _xlpm.d, _xlpm.getVal("d"), _xlpm.h, _xlpm.getVal("h"), _xlpm.m, _xlpm.getVal("m"), _xlpm.seconds, _xlpm.w*144000 + _xlpm.d*28800 + _xlpm.h*3600 + _xlpm.m*60, IF(_xlpm.seconds=0, "", _xlpm.seconds*60) ) )} | AK9: {=IFERROR( _xlfn.IFS( JiraDataset[[#This Row],[IssueType]] = cfg_type_comment,"SKIP", JiraDataset[[#This Row],[IssueType]] = cfg_type_skip,"SKIP", JiraDataset[[#This Row],[IssueType]] = cfg_type_note,"SKIP" ), cfg_type_workitem )} -> WorkItem
A10: High | B10: story | C10: SSO Integration | E10: Add OIDC SSO with corporate IdP | F10: =Config!$G$4 -> JITTP Version 1 | G10: jane.smith | H10: Backend | J10: 1 | K10: abc | L10: 3d | M10: 8 | N10: 7 | P10: =IF(JiraDataset[[#This Row],[IssueType]]="Epic",JiraDataset[[#This Row],[Summary]],"") | AE10: =IF(JiraDataset[[#This Row],[RowType]]=cfg_type_skip,"",IFERROR(VLOOKUP(JiraDataset[[#This Row],[Sprint Name]], Config!$D$4:$E$9, 2, FALSE), "")) | AF10: =IF(JiraDataset[[#This Row],[RowType]]=cfg_type_skip,"",_xlfn.XLOOKUP("Creation Marker", CfgAutofieldValues[Name], CfgAutofieldValues[Value])) -> jt-imported | AG10: =IF(JiraDataset[[#This Row],[RowType]]=cfg_type_skip,"",_xlfn.XLOOKUP("Feature Pod Label", CfgAutofieldValues[Name], CfgAutofieldValues[Value])) -> ft-group-1 | AH10: =IF(JiraDataset[[#This Row],[RowType]]=cfg_type_skip,"",IFERROR(VLOOKUP(JiraDataset[[#This Row],[Assignee.Name]], Config!$A$4:$B$24, 2, FALSE), "")) -> someID | AI10: =IF(JiraDataset[[#This Row],[RowType]]=cfg_type_skip,"",_xlfn.XLOOKUP("jira.project.key", CfgAutofieldValues[Name], CfgAutofieldValues[Value])) -> PRJ_KEY | AJ10: {=IF( JiraDataset[[#This Row],[RowType]]=cfg_type_skip, "", _xlfn.LET( _xlpm.p, _xlfn.TEXTSPLIT(JiraDataset[[#This Row],[Estimate]], " "), _xlpm.getVal, _xlfn.LAMBDA(_xlpm.u, IFERROR(VALUE(LEFT(_xlfn._xlws.FILTER(_xlpm.p, RIGHT(_xlpm.p,1)=_xlpm.u), LEN(_xlfn._xlws.FILTER(_xlpm.p, RIGHT(_xlpm.p,1)=_xlpm.u))-1)), 0)), _xlpm.w, _xlpm.getVal("w"), _xlpm.d, _xlpm.getVal("d"), _xlpm.h, _xlpm.getVal("h"), _xlpm.m, _xlpm.getVal("m"), _xlpm.seconds, _xlpm.w*144000 + _xlpm.d*28800 + _xlpm.h*3600 + _xlpm.m*60, IF(_xlpm.seconds=0, "", _xlpm.seconds*60) ) )} -> 5184000 | AK10: {=IFERROR( _xlfn.IFS( JiraDataset[[#This Row],[IssueType]] = cfg_type_comment,"SKIP", JiraDataset[[#This Row],[IssueType]] = cfg_type_skip,"SKIP", JiraDataset[[#This Row],[IssueType]] = cfg_type_note,"SKIP" ), cfg_type_workitem )} -> WorkItem
A11: Medium | B11: task | C11: Password Reset Flow | E11: Implement secure token-based reset | F11: =Config!$G$4 -> JITTP Version 1 | G11: Alice A | H11: Backend | J11: 1 | K11: abc | L11: 2d | M11: 9 | N11: 7 | P11: =IF(JiraDataset[[#This Row],[IssueType]]="Epic",JiraDataset[[#This Row],[Summary]],"") | AE11: =IF(JiraDataset[[#This Row],[RowType]]=cfg_type_skip,"",IFERROR(VLOOKUP(JiraDataset[[#This Row],[Sprint Name]], Config!$D$4:$E$9, 2, FALSE), "")) | AF11: =IF(JiraDataset[[#This Row],[RowType]]=cfg_type_skip,"",_xlfn.XLOOKUP("Creation Marker", CfgAutofieldValues[Name], CfgAutofieldValues[Value])) -> jt-imported | AG11: =IF(JiraDataset[[#This Row],[RowType]]=cfg_type_skip,"",_xlfn.XLOOKUP("Feature Pod Label", CfgAutofieldValues[Name], CfgAutofieldValues[Value])) -> ft-group-1 | AH11: =IF(JiraDataset[[#This Row],[RowType]]=cfg_type_skip,"",IFERROR(VLOOKUP(JiraDataset[[#This Row],[Assignee.Name]], Config!$A$4:$B$24, 2, FALSE), "")) -> someID | AI11: =IF(JiraDataset[[#This Row],[RowType]]=cfg_type_skip,"",_xlfn.XLOOKUP("jira.project.key", CfgAutofieldValues[Name], CfgAutofieldValues[Value])) -> PRJ_KEY | AJ11: {=IF( JiraDataset[[#This Row],[RowType]]=cfg_type_skip, "", _xlfn.LET( _xlpm.p, _xlfn.TEXTSPLIT(JiraDataset[[#This Row],[Estimate]], " "), _xlpm.getVal, _xlfn.LAMBDA(_xlpm.u, IFERROR(VALUE(LEFT(_xlfn._xlws.FILTER(_xlpm.p, RIGHT(_xlpm.p,1)=_xlpm.u), LEN(_xlfn._xlws.FILTER(_xlpm.p, RIGHT(_xlpm.p,1)=_xlpm.u))-1)), 0)), _xlpm.w, _xlpm.getVal("w"), _xlpm.d, _xlpm.getVal("d"), _xlpm.h, _xlpm.getVal("h"), _xlpm.m, _xlpm.getVal("m"), _xlpm.seconds, _xlpm.w*144000 + _xlpm.d*28800 + _xlpm.h*3600 + _xlpm.m*60, IF(_xlpm.seconds=0, "", _xlpm.seconds*60) ) )} -> 3456000 | AK11: {=IFERROR( _xlfn.IFS( JiraDataset[[#This Row],[IssueType]] = cfg_type_comment,"SKIP", JiraDataset[[#This Row],[IssueType]] = cfg_type_skip,"SKIP", JiraDataset[[#This Row],[IssueType]] = cfg_type_note,"SKIP" ), cfg_type_workitem )} -> WorkItem
A12: Highest | B12: bug | C12: Session Expiry Bug | E12: Sessions not invalidated on logout | F12: =Config!$G$4 -> JITTP Version 1 | G12: Bob B | H12: Backend | J12: 1 | K12: abc | L12: 4h | M12: 10 | N12: 7 | P12: =IF(JiraDataset[[#This Row],[IssueType]]="Epic",JiraDataset[[#This Row],[Summary]],"") | AE12: =IF(JiraDataset[[#This Row],[RowType]]=cfg_type_skip,"",IFERROR(VLOOKUP(JiraDataset[[#This Row],[Sprint Name]], Config!$D$4:$E$9, 2, FALSE), "")) | AF12: =IF(JiraDataset[[#This Row],[RowType]]=cfg_type_skip,"",_xlfn.XLOOKUP("Creation Marker", CfgAutofieldValues[Name], CfgAutofieldValues[Value])) -> jt-imported | AG12: =IF(JiraDataset[[#This Row],[RowType]]=cfg_type_skip,"",_xlfn.XLOOKUP("Feature Pod Label", CfgAutofieldValues[Name], CfgAutofieldValues[Value])) -> ft-group-1 | AH12: =IF(JiraDataset[[#This Row],[RowType]]=cfg_type_skip,"",IFERROR(VLOOKUP(JiraDataset[[#This Row],[Assignee.Name]], Config!$A$4:$B$24, 2, FALSE), "")) -> someID | AI12: =IF(JiraDataset[[#This Row],[RowType]]=cfg_type_skip,"",_xlfn.XLOOKUP("jira.project.key", CfgAutofieldValues[Name], CfgAutofieldValues[Value])) -> PRJ_KEY | AJ12: {=IF( JiraDataset[[#This Row],[RowType]]=cfg_type_skip, "", _xlfn.LET( _xlpm.p, _xlfn.TEXTSPLIT(JiraDataset[[#This Row],[Estimate]], " "), _xlpm.getVal, _xlfn.LAMBDA(_xlpm.u, IFERROR(VALUE(LEFT(_xlfn._xlws.FILTER(_xlpm.p, RIGHT(_xlpm.p,1)=_xlpm.u), LEN(_xlfn._xlws.FILTER(_xlpm.p, RIGHT(_xlpm.p,1)=_xlpm.u))-1)), 0)), _xlpm.w, _xlpm.getVal("w"), _xlpm.d, _xlpm.getVal("d"), _xlpm.h, _xlpm.getVal("h"), _xlpm.m, _xlpm.getVal("m"), _xlpm.seconds, _xlpm.w*144000 + _xlpm.d*28800 + _xlpm.h*3600 + _xlpm.m*60, IF(_xlpm.seconds=0, "", _xlpm.seconds*60) ) )} -> 864000 | AK12: {=IFERROR( _xlfn.IFS( JiraDataset[[#This Row],[IssueType]] = cfg_type_comment,"SKIP", JiraDataset[[#This Row],[IssueType]] = cfg_type_skip,"SKIP", JiraDataset[[#This Row],[IssueType]] = cfg_type_note,"SKIP" ), cfg_type_workitem )} -> WorkItem
A13: Low | B13: sub-task | C13: Add Tests for Reset Flow | E13: Write unit tests for reset controller | F13: =Config!$G$4 -> JITTP Version 1 | G13: joe.grunt | H13: Testing | J13: 1 | K13: abc | L13: 6h | M13: 11 | N13: 9 | P13: =IF(JiraDataset[[#This Row],[IssueType]]="Epic",JiraDataset[[#This Row],[Summary]],"") | AE13: =IF(JiraDataset[[#This Row],[RowType]]=cfg_type_skip,"",IFERROR(VLOOKUP(JiraDataset[[#This Row],[Sprint Name]], Config!$D$4:$E$9, 2, FALSE), "")) | AF13: =IF(JiraDataset[[#This Row],[RowType]]=cfg_type_skip,"",_xlfn.XLOOKUP("Creation Marker", CfgAutofieldValues[Name], CfgAutofieldValues[Value])) -> jt-imported | AG13: =IF(JiraDataset[[#This Row],[RowType]]=cfg_type_skip,"",_xlfn.XLOOKUP("Feature Pod Label", CfgAutofieldValues[Name], CfgAutofieldValues[Value])) -> ft-group-1 | AH13: =IF(JiraDataset[[#This Row],[RowType]]=cfg_type_skip,"",IFERROR(VLOOKUP(JiraDataset[[#This Row],[Assignee.Name]], Config!$A$4:$B$24, 2, FALSE), "")) -> someID | AI13: =IF(JiraDataset[[#This Row],[RowType]]=cfg_type_skip,"",_xlfn.XLOOKUP("jira.project.key", CfgAutofieldValues[Name], CfgAutofieldValues[Value])) -> PRJ_KEY | AJ13: {=IF( JiraDataset[[#This Row],[RowType]]=cfg_type_skip, "", _xlfn.LET( _xlpm.p, _xlfn.TEXTSPLIT(JiraDataset[[#This Row],[Estimate]], " "), _xlpm.getVal, _xlfn.LAMBDA(_xlpm.u, IFERROR(VALUE(LEFT(_xlfn._xlws.FILTER(_xlpm.p, RIGHT(_xlpm.p,1)=_xlpm.u), LEN(_xlfn._xlws.FILTER(_xlpm.p, RIGHT(_xlpm.p,1)=_xlpm.u))-1)), 0)), _xlpm.w, _xlpm.getVal("w"), _xlpm.d, _xlpm.getVal("d"), _xlpm.h, _xlpm.getVal("h"), _xlpm.m, _xlpm.getVal("m"), _xlpm.seconds, _xlpm.w*144000 + _xlpm.d*28800 + _xlpm.h*3600 + _xlpm.m*60, IF(_xlpm.seconds=0, "", _xlpm.seconds*60) ) )} -> 1296000 | AK13: {=IFERROR( _xlfn.IFS( JiraDataset[[#This Row],[IssueType]] = cfg_type_comment,"SKIP", JiraDataset[[#This Row],[IssueType]] = cfg_type_skip,"SKIP", JiraDataset[[#This Row],[IssueType]] = cfg_type_note,"SKIP" ), cfg_type_workitem )} -> WorkItem
A14: High | B14: epic | C14: Payments & Billing | E14: Stripe integration and invoicing | F14: =Config!$G$4 -> JITTP Version 1 | G14: john.doe | H14: Payments | J14: 1 | K14: abc | L14: 1w | M14: 12 | N14: 1 | P14: =IF(JiraDataset[[#This Row],[IssueType]]="Epic",JiraDataset[[#This Row],[Summary]],"") -> Payments & Billing | AE14: =IF(JiraDataset[[#This Row],[RowType]]=cfg_type_skip,"",IFERROR(VLOOKUP(JiraDataset[[#This Row],[Sprint Name]], Config!$D$4:$E$9, 2, FALSE), "")) | AF14: =IF(JiraDataset[[#This Row],[RowType]]=cfg_type_skip,"",_xlfn.XLOOKUP("Creation Marker", CfgAutofieldValues[Name], CfgAutofieldValues[Value])) -> jt-imported | AG14: =IF(JiraDataset[[#This Row],[RowType]]=cfg_type_skip,"",_xlfn.XLOOKUP("Feature Pod Label", CfgAutofieldValues[Name], CfgAutofieldValues[Value])) -> ft-group-1 | AH14: =IF(JiraDataset[[#This Row],[RowType]]=cfg_type_skip,"",IFERROR(VLOOKUP(JiraDataset[[#This Row],[Assignee.Name]], Config!$A$4:$B$24, 2, FALSE), "")) -> someID | AI14: =IF(JiraDataset[[#This Row],[RowType]]=cfg_type_skip,"",_xlfn.XLOOKUP("jira.project.key", CfgAutofieldValues[Name], CfgAutofieldValues[Value])) -> PRJ_KEY | AJ14: {=IF( JiraDataset[[#This Row],[RowType]]=cfg_type_skip, "", _xlfn.LET( _xlpm.p, _xlfn.TEXTSPLIT(JiraDataset[[#This Row],[Estimate]], " "), _xlpm.getVal, _xlfn.LAMBDA(_xlpm.u, IFERROR(VALUE(LEFT(_xlfn._xlws.FILTER(_xlpm.p, RIGHT(_xlpm.p,1)=_xlpm.u), LEN(_xlfn._xlws.FILTER(_xlpm.p, RIGHT(_xlpm.p,1)=_xlpm.u))-1)), 0)), _xlpm.w, _xlpm.getVal("w"), _xlpm.d, _xlpm.getVal("d"), _xlpm.h, _xlpm.getVal("h"), _xlpm.m, _xlpm.getVal("m"), _xlpm.seconds, _xlpm.w*144000 + _xlpm.d*28800 + _xlpm.h*3600 + _xlpm.m*60, IF(_xlpm.seconds=0, "", _xlpm.seconds*60) ) )} -> 8640000 | AK14: {=IFERROR( _xlfn.IFS( JiraDataset[[#This Row],[IssueType]] = cfg_type_comment,"SKIP", JiraDataset[[#This Row],[IssueType]] = cfg_type_skip,"SKIP", JiraDataset[[#This Row],[IssueType]] = cfg_type_note,"SKIP" ), cfg_type_workitem )} -> WorkItem
A15: Medium | B15: story | C15: Checkout API | E15: Implement server-side checkout | F15: =Config!$G$4 -> JITTP Version 1 | G15: jane.smith | H15: Backend | J15: 1 | K15: abc | L15: 3d | M15: 13 | N15: 12 | P15: =IF(JiraDataset[[#This Row],[IssueType]]="Epic",JiraDataset[[#This Row],[Summary]],"") | AE15: =IF(JiraDataset[[#This Row],[RowType]]=cfg_type_skip,"",IFERROR(VLOOKUP(JiraDataset[[#This Row],[Sprint Name]], Config!$D$4:$E$9, 2, FALSE), "")) | AF15: =IF(JiraDataset[[#This Row],[RowType]]=cfg_type_skip,"",_xlfn.XLOOKUP("Creation Marker", CfgAutofieldValues[Name], CfgAutofieldValues[Value])) -> jt-imported | AG15: =IF(JiraDataset[[#This Row],[RowType]]=cfg_type_skip,"",_xlfn.XLOOKUP("Feature Pod Label", CfgAutofieldValues[Name], CfgAutofieldValues[Value])) -> ft-group-1 | AH15: =IF(JiraDataset[[#This Row],[RowType]]=cfg_type_skip,"",IFERROR(VLOOKUP(JiraDataset[[#This Row],[Assignee.Name]], Config!$A$4:$B$24, 2, FALSE), "")) -> someID | AI15: =IF(JiraDataset[[#This Row],[RowType]]=cfg_type_skip,"",_xlfn.XLOOKUP("jira.project.key", CfgAutofieldValues[Name], CfgAutofieldValues[Value])) -> PRJ_KEY | AJ15: {=IF( JiraDataset[[#This Row],[RowType]]=cfg_type_skip, "", _xlfn.LET( _xlpm.p, _xlfn.TEXTSPLIT(JiraDataset[[#This Row],[Estimate]], " "), _xlpm.getVal, _xlfn.LAMBDA(_xlpm.u, IFERROR(VALUE(LEFT(_xlfn._xlws.FILTER(_xlpm.p, RIGHT(_xlpm.p,1)=_xlpm.u), LEN(_xlfn._xlws.FILTER(_xlpm.p, RIGHT(_xlpm.p,1)=_xlpm.u))-1)), 0)), _xlpm.w, _xlpm.getVal("w"), _xlpm.d, _xlpm.getVal("d"), _xlpm.h, _xlpm.getVal("h"), _xlpm.m, _xlpm.getVal("m"), _xlpm.seconds, _xlpm.w*144000 + _xlpm.d*28800 + _xlpm.h*3600 + _xlpm.m*60, IF(_xlpm.seconds=0, "", _xlpm.seconds*60) ) )} -> 5184000 | AK15: {=IFERROR( _xlfn.IFS( JiraDataset[[#This Row],[IssueType]] = cfg_type_comment,"SKIP", JiraDataset[[#This Row],[IssueType]] = cfg_type_skip,"SKIP", JiraDataset[[#This Row],[IssueType]] = cfg_type_note,"SKIP" ), cfg_type_workitem )} -> WorkItem
A16: Lowest | B16: task | C16: Checkout UI | E16: Build cart and checkout screens | F16: =Config!$G$4 -> JITTP Version 1 | G16: Alice A | H16: Frontend | J16: 1 | K16: abc | L16: 2d | M16: 14 | N16: 12 | P16: =IF(JiraDataset[[#This Row],[IssueType]]="Epic",JiraDataset[[#This Row],[Summary]],"") | AE16: =IF(JiraDataset[[#This Row],[RowType]]=cfg_type_skip,"",IFERROR(VLOOKUP(JiraDataset[[#This Row],[Sprint Name]], Config!$D$4:$E$9, 2, FALSE), "")) | AF16: =IF(JiraDataset[[#This Row],[RowType]]=cfg_type_skip,"",_xlfn.XLOOKUP("Creation Marker", CfgAutofieldValues[Name], CfgAutofieldValues[Value])) -> jt-imported | AG16: =IF(JiraDataset[[#This Row],[RowType]]=cfg_type_skip,"",_xlfn.XLOOKUP("Feature Pod Label", CfgAutofieldValues[Name], CfgAutofieldValues[Value])) -> ft-group-1 | AH16: =IF(JiraDataset[[#This Row],[RowType]]=cfg_type_skip,"",IFERROR(VLOOKUP(JiraDataset[[#This Row],[Assignee.Name]], Config!$A$4:$B$24, 2, FALSE), "")) -> someID | AI16: =IF(JiraDataset[[#This Row],[RowType]]=cfg_type_skip,"",_xlfn.XLOOKUP("jira.project.key", CfgAutofieldValues[Name], CfgAutofieldValues[Value])) -> PRJ_KEY | AJ16: {=IF( JiraDataset[[#This Row],[RowType]]=cfg_type_skip, "", _xlfn.LET( _xlpm.p, _xlfn.TEXTSPLIT(JiraDataset[[#This Row],[Estimate]], " "), _xlpm.getVal, _xlfn.LAMBDA(_xlpm.u, IFERROR(VALUE(LEFT(_xlfn._xlws.FILTER(_xlpm.p, RIGHT(_xlpm.p,1)=_xlpm.u), LEN(_xlfn._xlws.FILTER(_xlpm.p, RIGHT(_xlpm.p,1)=_xlpm.u))-1)), 0)), _xlpm.w, _xlpm.getVal("w"), _xlpm.d, _xlpm.getVal("d"), _xlpm.h, _xlpm.getVal("h"), _xlpm.m, _xlpm.getVal("m"), _xlpm.seconds, _xlpm.w*144000 + _xlpm.d*28800 + _xlpm.h*3600 + _xlpm.m*60, IF(_xlpm.seconds=0, "", _xlpm.seconds*60) ) )} -> 3456000 | AK16: {=IFERROR( _xlfn.IFS( JiraDataset[[#This Row],[IssueType]] = cfg_type_comment,"SKIP", JiraDataset[[#This Row],[IssueType]] = cfg_type_skip,"SKIP", JiraDataset[[#This Row],[IssueType]] = cfg_type_note,"SKIP" ), cfg_type_workitem )} -> WorkItem
A17: Triage | B17: bug | C17: Currency Rounding Error | E17: Rounding differs between UI/API | F17: =Config!$G$4 -> JITTP Version 1 | G17: Bob B | H17: Frontend | J17: 1 | K17: abc | L17: 1d | M17: 15 | N17: 12 | P17: =IF(JiraDataset[[#This Row],[IssueType]]="Epic",JiraDataset[[#This Row],[Summary]],"") | AE17: =IF(JiraDataset[[#This Row],[RowType]]=cfg_type_skip,"",IFERROR(VLOOKUP(JiraDataset[[#This Row],[Sprint Name]], Config!$D$4:$E$9, 2, FALSE), "")) | AF17: =IF(JiraDataset[[#This Row],[RowType]]=cfg_type_skip,"",_xlfn.XLOOKUP("Creation Marker", CfgAutofieldValues[Name], CfgAutofieldValues[Value])) -> jt-imported | AG17: =IF(JiraDataset[[#This Row],[RowType]]=cfg_type_skip,"",_xlfn.XLOOKUP("Feature Pod Label", CfgAutofieldValues[Name], CfgAutofieldValues[Value])) -> ft-group-1 | AH17: =IF(JiraDataset[[#This Row],[RowType]]=cfg_type_skip,"",IFERROR(VLOOKUP(JiraDataset[[#This Row],[Assignee.Name]], Config!$A$4:$B$24, 2, FALSE), "")) -> someID | AI17: =IF(JiraDataset[[#This Row],[RowType]]=cfg_type_skip,"",_xlfn.XLOOKUP("jira.project.key", CfgAutofieldValues[Name], CfgAutofieldValues[Value])) -> PRJ_KEY | AJ17: {=IF( JiraDataset[[#This Row],[RowType]]=cfg_type_skip, "", _xlfn.LET( _xlpm.p, _xlfn.TEXTSPLIT(JiraDataset[[#This Row],[Estimate]], " "), _xlpm.getVal, _xlfn.LAMBDA(_xlpm.u, IFERROR(VALUE(LEFT(_xlfn._xlws.FILTER(_xlpm.p, RIGHT(_xlpm.p,1)=_xlpm.u), LEN(_xlfn._xlws.FILTER(_xlpm.p, RIGHT(_xlpm.p,1)=_xlpm.u))-1)), 0)), _xlpm.w, _xlpm.getVal("w"), _xlpm.d, _xlpm.getVal("d"), _xlpm.h, _xlpm.getVal("h"), _xlpm.m, _xlpm.getVal("m"), _xlpm.seconds, _xlpm.w*144000 + _xlpm.d*28800 + _xlpm.h*3600 + _xlpm.m*60, IF(_xlpm.seconds=0, "", _xlpm.seconds*60) ) )} -> 1728000 | AK17: {=IFERROR( _xlfn.IFS( JiraDataset[[#This Row],[IssueType]] = cfg_type_comment,"SKIP", JiraDataset[[#This Row],[IssueType]] = cfg_type_skip,"SKIP", JiraDataset[[#This Row],[IssueType]] = cfg_type_note,"SKIP" ), cfg_type_workitem )} -> WorkItem
A18: Medium | B18: sub-task | C18: Edge-Case Tests | E18: Add e2e tests for failed payments | F18: =Config!$G$4 -> JITTP Version 1 | G18: joe.grunt | H18: Testing | J18: 1 | K18: abc | L18: 1d | M18: 16 | N18: 13 | P18: =IF(JiraDataset[[#This Row],[IssueType]]="Epic",JiraDataset[[#This Row],[Summary]],"") | AE18: =IF(JiraDataset[[#This Row],[RowType]]=cfg_type_skip,"",IFERROR(VLOOKUP(JiraDataset[[#This Row],[Sprint Name]], Config!$D$4:$E$9, 2, FALSE), "")) | AF18: =IF(JiraDataset[[#This Row],[RowType]]=cfg_type_skip,"",_xlfn.XLOOKUP("Creation Marker", CfgAutofieldValues[Name], CfgAutofieldValues[Value])) -> jt-imported | AG18: =IF(JiraDataset[[#This Row],[RowType]]=cfg_type_skip,"",_xlfn.XLOOKUP("Feature Pod Label", CfgAutofieldValues[Name], CfgAutofieldValues[Value])) -> ft-group-1 | AH18: =IF(JiraDataset[[#This Row],[RowType]]=cfg_type_skip,"",IFERROR(VLOOKUP(JiraDataset[[#This Row],[Assignee.Name]], Config!$A$4:$B$24, 2, FALSE), "")) -> someID | AI18: =IF(JiraDataset[[#This Row],[RowType]]=cfg_type_skip,"",_xlfn.XLOOKUP("jira.project.key", CfgAutofieldValues[Name], CfgAutofieldValues[Value])) -> PRJ_KEY | AJ18: {=IF( JiraDataset[[#This Row],[RowType]]=cfg_type_skip, "", _xlfn.LET( _xlpm.p, _xlfn.TEXTSPLIT(JiraDataset[[#This Row],[Estimate]], " "), _xlpm.getVal, _xlfn.LAMBDA(_xlpm.u, IFERROR(VALUE(LEFT(_xlfn._xlws.FILTER(_xlpm.p, RIGHT(_xlpm.p,1)=_xlpm.u), LEN(_xlfn._xlws.FILTER(_xlpm.p, RIGHT(_xlpm.p,1)=_xlpm.u))-1)), 0)), _xlpm.w, _xlpm.getVal("w"), _xlpm.d, _xlpm.getVal("d"), _xlpm.h, _xlpm.getVal("h"), _xlpm.m, _xlpm.getVal("m"), _xlpm.seconds, _xlpm.w*144000 + _xlpm.d*28800 + _xlpm.h*3600 + _xlpm.m*60, IF(_xlpm.seconds=0, "", _xlpm.seconds*60) ) )} -> 1728000 | AK18: {=IFERROR( _xlfn.IFS( JiraDataset[[#This Row],[IssueType]] = cfg_type_comment,"SKIP", JiraDataset[[#This Row],[IssueType]] = cfg_type_skip,"SKIP", JiraDataset[[#This Row],[IssueType]] = cfg_type_note,"SKIP" ), cfg_type_workitem )} -> WorkItem
A19: High | B19: initiative | C19: Mobile & Growth | E19: Mobile-first initiative to grow MAU | F19: =Config!$G$4 -> JITTP Version 1 | G19: john.doe | H19: Strategy | J19: 1 | K19: abc | L19: 2w | M19: 17 | P19: =IF(JiraDataset[[#This Row],[IssueType]]="Epic",JiraDataset[[#This Row],[Summary]],"") | AE19: =IF(JiraDataset[[#This Row],[RowType]]=cfg_type_skip,"",IFERROR(VLOOKUP(JiraDataset[[#This Row],[Sprint Name]], Config!$D$4:$E$9, 2, FALSE), "")) | AF19: =IF(JiraDataset[[#This Row],[RowType]]=cfg_type_skip,"",_xlfn.XLOOKUP("Creation Marker", CfgAutofieldValues[Name], CfgAutofieldValues[Value])) -> jt-imported | AG19: =IF(JiraDataset[[#This Row],[RowType]]=cfg_type_skip,"",_xlfn.XLOOKUP("Feature Pod Label", CfgAutofieldValues[Name], CfgAutofieldValues[Value])) -> ft-group-1 | AH19: =IF(JiraDataset[[#This Row],[RowType]]=cfg_type_skip,"",IFERROR(VLOOKUP(JiraDataset[[#This Row],[Assignee.Name]], Config!$A$4:$B$24, 2, FALSE), "")) -> someID | AI19: =IF(JiraDataset[[#This Row],[RowType]]=cfg_type_skip,"",_xlfn.XLOOKUP("jira.project.key", CfgAutofieldValues[Name], CfgAutofieldValues[Value])) -> PRJ_KEY | AJ19: {=IF( JiraDataset[[#This Row],[RowType]]=cfg_type_skip, "", _xlfn.LET( _xlpm.p, _xlfn.TEXTSPLIT(JiraDataset[[#This Row],[Estimate]], " "), _xlpm.getVal, _xlfn.LAMBDA(_xlpm.u, IFERROR(VALUE(LEFT(_xlfn._xlws.FILTER(_xlpm.p, RIGHT(_xlpm.p,1)=_xlpm.u), LEN(_xlfn._xlws.FILTER(_xlpm.p, RIGHT(_xlpm.p,1)=_xlpm.u))-1)), 0)), _xlpm.w, _xlpm.getVal("w"), _xlpm.d, _xlpm.getVal("d"), _xlpm.h, _xlpm.getVal("h"), _xlpm.m, _xlpm.getVal("m"), _xlpm.seconds, _xlpm.w*144000 + _xlpm.d*28800 + _xlpm.h*3600 + _xlpm.m*60, IF(_xlpm.seconds=0, "", _xlpm.seconds*60) ) )} -> 17280000 | AK19: {=IFERROR( _xlfn.IFS( JiraDataset[[#This Row],[IssueType]] = cfg_type_comment,"SKIP", JiraDataset[[#This Row],[IssueType]] = cfg_type_skip,"SKIP", JiraDataset[[#This Row],[IssueType]] = cfg_type_note,"SKIP" ), cfg_type_workitem )} -> WorkItem
A20: Medium | B20: epic | C20: Mobile App UX | E20: Refine navigation and gestures on mobile | F20: =Config!$G$4 -> JITTP Version 1 | G20: jane.smith | H20: Frontend | J20: 1 | K20: abc | L20: 1w | M20: 18 | N20: 17 | P20: =IF(JiraDataset[[#This Row],[IssueType]]="Epic",JiraDataset[[#This Row],[Summary]],"") -> Mobile App UX | AE20: =IF(JiraDataset[[#This Row],[RowType]]=cfg_type_skip,"",IFERROR(VLOOKUP(JiraDataset[[#This Row],[Sprint Name]], Config!$D$4:$E$9, 2, FALSE), "")) | AF20: =IF(JiraDataset[[#This Row],[RowType]]=cfg_type_skip,"",_xlfn.XLOOKUP("Creation Marker", CfgAutofieldValues[Name], CfgAutofieldValues[Value])) -> jt-imported | AG20: =IF(JiraDataset[[#This Row],[RowType]]=cfg_type_skip,"",_xlfn.XLOOKUP("Feature Pod Label", CfgAutofieldValues[Name], CfgAutofieldValues[Value])) -> ft-group-1 | AH20: =IF(JiraDataset[[#This Row],[RowType]]=cfg_type_skip,"",IFERROR(VLOOKUP(JiraDataset[[#This Row],[Assignee.Name]], Config!$A$4:$B$24, 2, FALSE), "")) -> someID | AI20: =IF(JiraDataset[[#This Row],[RowType]]=cfg_type_skip,"",_xlfn.XLOOKUP("jira.project.key", CfgAutofieldValues[Name], CfgAutofieldValues[Value])) -> PRJ_KEY | AJ20: {=IF( JiraDataset[[#This Row],[RowType]]=cfg_type_skip, "", _xlfn.LET( _xlpm.p, _xlfn.TEXTSPLIT(JiraDataset[[#This Row],[Estimate]], " "), _xlpm.getVal, _xlfn.LAMBDA(_xlpm.u, IFERROR(VALUE(LEFT(_xlfn._xlws.FILTER(_xlpm.p, RIGHT(_xlpm.p,1)=_xlpm.u), LEN(_xlfn._xlws.FILTER(_xlpm.p, RIGHT(_xlpm.p,1)=_xlpm.u))-1)), 0)), _xlpm.w, _xlpm.getVal("w"), _xlpm.d, _xlpm.getVal("d"), _xlpm.h, _xlpm.getVal("h"), _xlpm.m, _xlpm.getVal("m"), _xlpm.seconds, _xlpm.w*144000 + _xlpm.d*28800 + _xlpm.h*3600 + _xlpm.m*60, IF(_xlpm.seconds=0, "", _xlpm.seconds*60) ) )} -> 8640000 | AK20: {=IFERROR( _xlfn.IFS( JiraDataset[[#This Row],[IssueType]] = cfg_type_comment,"SKIP", JiraDataset[[#This Row],[IssueType]] = cfg_type_skip,"SKIP", JiraDataset[[#This Row],[IssueType]] = cfg_type_note,"SKIP" ), cfg_type_workitem )} -> WorkItem
A21: Highest | B21: story | C21: Responsive Layout | E21: Implement responsive grid and breakpoints | F21: =Config!$G$4 -> JITTP Version 1 | G21: Alice A | H21: Frontend | J21: 1 | K21: abc | L21: 3d | M21: 19 | N21: 18 | P21: =IF(JiraDataset[[#This Row],[IssueType]]="Epic",JiraDataset[[#This Row],[Summary]],"") | AE21: =IF(JiraDataset[[#This Row],[RowType]]=cfg_type_skip,"",IFERROR(VLOOKUP(JiraDataset[[#This Row],[Sprint Name]], Config!$D$4:$E$9, 2, FALSE), "")) | AF21: =IF(JiraDataset[[#This Row],[RowType]]=cfg_type_skip,"",_xlfn.XLOOKUP("Creation Marker", CfgAutofieldValues[Name], CfgAutofieldValues[Value])) -> jt-imported | AG21: =IF(JiraDataset[[#This Row],[RowType]]=cfg_type_skip,"",_xlfn.XLOOKUP("Feature Pod Label", CfgAutofieldValues[Name], CfgAutofieldValues[Value])) -> ft-group-1 | AH21: =IF(JiraDataset[[#This Row],[RowType]]=cfg_type_skip,"",IFERROR(VLOOKUP(JiraDataset[[#This Row],[Assignee.Name]], Config!$A$4:$B$24, 2, FALSE), "")) -> someID | AI21: =IF(JiraDataset[[#This Row],[RowType]]=cfg_type_skip,"",_xlfn.XLOOKUP("jira.project.key", CfgAutofieldValues[Name], CfgAutofieldValues[Value])) -> PRJ_KEY | AJ21: {=IF( JiraDataset[[#This Row],[RowType]]=cfg_type_skip, "", _xlfn.LET( _xlpm.p, _xlfn.TEXTSPLIT(JiraDataset[[#This Row],[Estimate]], " "), _xlpm.getVal, _xlfn.LAMBDA(_xlpm.u, IFERROR(VALUE(LEFT(_xlfn._xlws.FILTER(_xlpm.p, RIGHT(_xlpm.p,1)=_xlpm.u), LEN(_xlfn._xlws.FILTER(_xlpm.p, RIGHT(_xlpm.p,1)=_xlpm.u))-1)), 0)), _xlpm.w, _xlpm.getVal("w"), _xlpm.d, _xlpm.getVal("d"), _xlpm.h, _xlpm.getVal("h"), _xlpm.m, _xlpm.getVal("m"), _xlpm.seconds, _xlpm.w*144000 + _xlpm.d*28800 + _xlpm.h*3600 + _xlpm.m*60, IF(_xlpm.seconds=0, "", _xlpm.seconds*60) ) )} -> 5184000 | AK21: {=IFERROR( _xlfn.IFS( JiraDataset[[#This Row],[IssueType]] = cfg_type_comment,"SKIP", JiraDataset[[#This Row],[IssueType]] = cfg_type_skip,"SKIP", JiraDataset[[#This Row],[IssueType]] = cfg_type_note,"SKIP" ), cfg_type_workitem )} -> WorkItem
A22: High | B22: task | C22: Touch Gestures | E22: Add swipe/long-press interactions | F22: =Config!$G$4 -> JITTP Version 1 | G22: Bob B | H22: Frontend | J22: 1 | K22: abc | L22: 2d | M22: 20 | N22: 18 | P22: =IF(JiraDataset[[#This Row],[IssueType]]="Epic",JiraDataset[[#This Row],[Summary]],"") | AE22: =IF(JiraDataset[[#This Row],[RowType]]=cfg_type_skip,"",IFERROR(VLOOKUP(JiraDataset[[#This Row],[Sprint Name]], Config!$D$4:$E$9, 2, FALSE), "")) | AF22: =IF(JiraDataset[[#This Row],[RowType]]=cfg_type_skip,"",_xlfn.XLOOKUP("Creation Marker", CfgAutofieldValues[Name], CfgAutofieldValues[Value])) -> jt-imported | AG22: =IF(JiraDataset[[#This Row],[RowType]]=cfg_type_skip,"",_xlfn.XLOOKUP("Feature Pod Label", CfgAutofieldValues[Name], CfgAutofieldValues[Value])) -> ft-group-1 | AH22: =IF(JiraDataset[[#This Row],[RowType]]=cfg_type_skip,"",IFERROR(VLOOKUP(JiraDataset[[#This Row],[Assignee.Name]], Config!$A$4:$B$24, 2, FALSE), "")) -> someID | AI22: =IF(JiraDataset[[#This Row],[RowType]]=cfg_type_skip,"",_xlfn.XLOOKUP("jira.project.key", CfgAutofieldValues[Name], CfgAutofieldValues[Value])) -> PRJ_KEY | AJ22: {=IF( JiraDataset[[#This Row],[RowType]]=cfg_type_skip, "", _xlfn.LET( _xlpm.p, _xlfn.TEXTSPLIT(JiraDataset[[#This Row],[Estimate]], " "), _xlpm.getVal, _xlfn.LAMBDA(_xlpm.u, IFERROR(VALUE(LEFT(_xlfn._xlws.FILTER(_xlpm.p, RIGHT(_xlpm.p,1)=_xlpm.u), LEN(_xlfn._xlws.FILTER(_xlpm.p, RIGHT(_xlpm.p,1)=_xlpm.u))-1)), 0)), _xlpm.w, _xlpm.getVal("w"), _xlpm.d, _xlpm.getVal("d"), _xlpm.h, _xlpm.getVal("h"), _xlpm.m, _xlpm.getVal("m"), _xlpm.seconds, _xlpm.w*144000 + _xlpm.d*28800 + _xlpm.h*3600 + _xlpm.m*60, IF(_xlpm.seconds=0, "", _xlpm.seconds*60) ) )} -> 3456000 | AK22: {=IFERROR( _xlfn.IFS( JiraDataset[[#This Row],[IssueType]] = cfg_type_comment,"SKIP", JiraDataset[[#This Row],[IssueType]] = cfg_type_skip,"SKIP", JiraDataset[[#This Row],[IssueType]] = cfg_type_note,"SKIP" ), cfg_type_workitem )} -> WorkItem
A23: Low | B23: bug | C23: Gesture Misfire Bug | E23: Swipe back triggers on tap | F23: =Config!$G$4 -> JITTP Version 1 | G23: joe.grunt | H23: Frontend | J23: 1 | K23: abc | L23: 6h | M23: 21 | N23: 18 | P23: =IF(JiraDataset[[#This Row],[IssueType]]="Epic",JiraDataset[[#This Row],[Summary]],"") | AE23: =IF(JiraDataset[[#This Row],[RowType]]=cfg_type_skip,"",IFERROR(VLOOKUP(JiraDataset[[#This Row],[Sprint Name]], Config!$D$4:$E$9, 2, FALSE), "")) | AF23: =IF(JiraDataset[[#This Row],[RowType]]=cfg_type_skip,"",_xlfn.XLOOKUP("Creation Marker", CfgAutofieldValues[Name], CfgAutofieldValues[Value])) -> jt-imported | AG23: =IF(JiraDataset[[#This Row],[RowType]]=cfg_type_skip,"",_xlfn.XLOOKUP("Feature Pod Label", CfgAutofieldValues[Name], CfgAutofieldValues[Value])) -> ft-group-1 | AH23: =IF(JiraDataset[[#This Row],[RowType]]=cfg_type_skip,"",IFERROR(VLOOKUP(JiraDataset[[#This Row],[Assignee.Name]], Config!$A$4:$B$24, 2, FALSE), "")) -> someID | AI23: =IF(JiraDataset[[#This Row],[RowType]]=cfg_type_skip,"",_xlfn.XLOOKUP("jira.project.key", CfgAutofieldValues[Name], CfgAutofieldValues[Value])) -> PRJ_KEY | AJ23: {=IF( JiraDataset[[#This Row],[RowType]]=cfg_type_skip, "", _xlfn.LET( _xlpm.p, _xlfn.TEXTSPLIT(JiraDataset[[#This Row],[Estimate]], " "), _xlpm.getVal, _xlfn.LAMBDA(_xlpm.u, IFERROR(VALUE(LEFT(_xlfn._xlws.FILTER(_xlpm.p, RIGHT(_xlpm.p,1)=_xlpm.u), LEN(_xlfn._xlws.FILTER(_xlpm.p, RIGHT(_xlpm.p,1)=_xlpm.u))-1)), 0)), _xlpm.w, _xlpm.getVal("w"), _xlpm.d, _xlpm.getVal("d"), _xlpm.h, _xlpm.getVal("h"), _xlpm.m, _xlpm.getVal("m"), _xlpm.seconds, _xlpm.w*144000 + _xlpm.d*28800 + _xlpm.h*3600 + _xlpm.m*60, IF(_xlpm.seconds=0, "", _xlpm.seconds*60) ) )} -> 1296000 | AK23: {=IFERROR( _xlfn.IFS( JiraDataset[[#This Row],[IssueType]] = cfg_type_comment,"SKIP", JiraDataset[[#This Row],[IssueType]] = cfg_type_skip,"SKIP", JiraDataset[[#This Row],[IssueType]] = cfg_type_note,"SKIP" ), cfg_type_workitem )} -> WorkItem
A24: Lowest | B24: sub-task | C24: Gesture Regression Tests | E24: Automate gesture tests on devices | F24: =Config!$G$4 -> JITTP Version 1 | G24: john.doe | H24: Testing | J24: 1 | K24: abc | L24: 1d | M24: 22 | N24: 21 | P24: =IF(JiraDataset[[#This Row],[IssueType]]="Epic",JiraDataset[[#This Row],[Summary]],"") | AE24: =IF(JiraDataset[[#This Row],[RowType]]=cfg_type_skip,"",IFERROR(VLOOKUP(JiraDataset[[#This Row],[Sprint Name]], Config!$D$4:$E$9, 2, FALSE), "")) | AF24: =IF(JiraDataset[[#This Row],[RowType]]=cfg_type_skip,"",_xlfn.XLOOKUP("Creation Marker", CfgAutofieldValues[Name], CfgAutofieldValues[Value])) -> jt-imported | AG24: =IF(JiraDataset[[#This Row],[RowType]]=cfg_type_skip,"",_xlfn.XLOOKUP("Feature Pod Label", CfgAutofieldValues[Name], CfgAutofieldValues[Value])) -> ft-group-1 | AH24: =IF(JiraDataset[[#This Row],[RowType]]=cfg_type_skip,"",IFERROR(VLOOKUP(JiraDataset[[#This Row],[Assignee.Name]], Config!$A$4:$B$24, 2, FALSE), "")) -> someID | AI24: =IF(JiraDataset[[#This Row],[RowType]]=cfg_type_skip,"",_xlfn.XLOOKUP("jira.project.key", CfgAutofieldValues[Name], CfgAutofieldValues[Value])) -> PRJ_KEY | AJ24: {=IF( JiraDataset[[#This Row],[RowType]]=cfg_type_skip, "", _xlfn.LET( _xlpm.p, _xlfn.TEXTSPLIT(JiraDataset[[#This Row],[Estimate]], " "), _xlpm.getVal, _xlfn.LAMBDA(_xlpm.u, IFERROR(VALUE(LEFT(_xlfn._xlws.FILTER(_xlpm.p, RIGHT(_xlpm.p,1)=_xlpm.u), LEN(_xlfn._xlws.FILTER(_xlpm.p, RIGHT(_xlpm.p,1)=_xlpm.u))-1)), 0)), _xlpm.w, _xlpm.getVal("w"), _xlpm.d, _xlpm.getVal("d"), _xlpm.h, _xlpm.getVal("h"), _xlpm.m, _xlpm.getVal("m"), _xlpm.seconds, _xlpm.w*144000 + _xlpm.d*28800 + _xlpm.h*3600 + _xlpm.m*60, IF(_xlpm.seconds=0, "", _xlpm.seconds*60) ) )} -> 1728000 | AK24: {=IFERROR( _xlfn.IFS( JiraDataset[[#This Row],[IssueType]] = cfg_type_comment,"SKIP", JiraDataset[[#This Row],[IssueType]] = cfg_type_skip,"SKIP", JiraDataset[[#This Row],[IssueType]] = cfg_type_note,"SKIP" ), cfg_type_workitem )} -> WorkItem
A25: Triage | B25: epic | C25: Admin & Permissions | E25: Granular roles and permissions | F25: =Config!$G$4 -> JITTP Version 1 | G25: jane.smith | H25: Security | J25: 1 | K25: abc | L25: 1w | M25: 23 | N25: 17 | P25: =IF(JiraDataset[[#This Row],[IssueType]]="Epic",JiraDataset[[#This Row],[Summary]],"") -> Admin & Permissions | AE25: =IF(JiraDataset[[#This Row],[RowType]]=cfg_type_skip,"",IFERROR(VLOOKUP(JiraDataset[[#This Row],[Sprint Name]], Config!$D$4:$E$9, 2, FALSE), "")) | AF25: =IF(JiraDataset[[#This Row],[RowType]]=cfg_type_skip,"",_xlfn.XLOOKUP("Creation Marker", CfgAutofieldValues[Name], CfgAutofieldValues[Value])) -> jt-imported | AG25: =IF(JiraDataset[[#This Row],[RowType]]=cfg_type_skip,"",_xlfn.XLOOKUP("Feature Pod Label", CfgAutofieldValues[Name], CfgAutofieldValues[Value])) -> ft-group-1 | AH25: =IF(JiraDataset[[#This Row],[RowType]]=cfg_type_skip,"",IFERROR(VLOOKUP(JiraDataset[[#This Row],[Assignee.Name]], Config!$A$4:$B$24, 2, FALSE), "")) -> someID | AI25: =IF(JiraDataset[[#This Row],[RowType]]=cfg_type_skip,"",_xlfn.XLOOKUP("jira.project.key", CfgAutofieldValues[Name], CfgAutofieldValues[Value])) -> PRJ_KEY | AJ25: {=IF( JiraDataset[[#This Row],[RowType]]=cfg_type_skip, "", _xlfn.LET( _xlpm.p, _xlfn.TEXTSPLIT(JiraDataset[[#This Row],[Estimate]], " "), _xlpm.getVal, _xlfn.LAMBDA(_xlpm.u, IFERROR(VALUE(LEFT(_xlfn._xlws.FILTER(_xlpm.p, RIGHT(_xlpm.p,1)=_xlpm.u), LEN(_xlfn._xlws.FILTER(_xlpm.p, RIGHT(_xlpm.p,1)=_xlpm.u))-1)), 0)), _xlpm.w, _xlpm.getVal("w"), _xlpm.d, _xlpm.getVal("d"), _xlpm.h, _xlpm.getVal("h"), _xlpm.m, _xlpm.getVal("m"), _xlpm.seconds, _xlpm.w*144000 + _xlpm.d*28800 + _xlpm.h*3600 + _xlpm.m*60, IF(_xlpm.seconds=0, "", _xlpm.seconds*60) ) )} -> 8640000 | AK25: {=IFERROR( _xlfn.IFS( JiraDataset[[#This Row],[IssueType]] = cfg_type_comment,"SKIP", JiraDataset[[#This Row],[IssueType]] = cfg_type_skip,"SKIP", JiraDataset[[#This Row],[IssueType]] = cfg_type_note,"SKIP" ), cfg_type_workitem )} -> WorkItem
A26: High | B26: story | C26: Role Model Design | E26: Define roles/claims and inheritance | F26: =Config!$G$4 -> JITTP Version 1 | G26: Alice A | H26: Backend | J26: 1 | K26: abc | L26: 2d | M26: 24 | N26: 23 | P26: =IF(JiraDataset[[#This Row],[IssueType]]="Epic",JiraDataset[[#This Row],[Summary]],"") | AE26: =IF(JiraDataset[[#This Row],[RowType]]=cfg_type_skip,"",IFERROR(VLOOKUP(JiraDataset[[#This Row],[Sprint Name]], Config!$D$4:$E$9, 2, FALSE), "")) | AF26: =IF(JiraDataset[[#This Row],[RowType]]=cfg_type_skip,"",_xlfn.XLOOKUP("Creation Marker", CfgAutofieldValues[Name], CfgAutofieldValues[Value])) -> jt-imported | AG26: =IF(JiraDataset[[#This Row],[RowType]]=cfg_type_skip,"",_xlfn.XLOOKUP("Feature Pod Label", CfgAutofieldValues[Name], CfgAutofieldValues[Value])) -> ft-group-1 | AH26: =IF(JiraDataset[[#This Row],[RowType]]=cfg_type_skip,"",IFERROR(VLOOKUP(JiraDataset[[#This Row],[Assignee.Name]], Config!$A$4:$B$24, 2, FALSE), "")) -> someID | AI26: =IF(JiraDataset[[#This Row],[RowType]]=cfg_type_skip,"",_xlfn.XLOOKUP("jira.project.key", CfgAutofieldValues[Name], CfgAutofieldValues[Value])) -> PRJ_KEY | AJ26: {=IF( JiraDataset[[#This Row],[RowType]]=cfg_type_skip, "", _xlfn.LET( _xlpm.p, _xlfn.TEXTSPLIT(JiraDataset[[#This Row],[Estimate]], " "), _xlpm.getVal, _xlfn.LAMBDA(_xlpm.u, IFERROR(VALUE(LEFT(_xlfn._xlws.FILTER(_xlpm.p, RIGHT(_xlpm.p,1)=_xlpm.u), LEN(_xlfn._xlws.FILTER(_xlpm.p, RIGHT(_xlpm.p,1)=_xlpm.u))-1)), 0)), _xlpm.w, _xlpm.getVal("w"), _xlpm.d, _xlpm.getVal("d"), _xlpm.h, _xlpm.getVal("h"), _xlpm.m, _xlpm.getVal("m"), _xlpm.seconds, _xlpm.w*144000 + _xlpm.d*28800 + _xlpm.h*3600 + _xlpm.m*60, IF(_xlpm.seconds=0, "", _xlpm.seconds*60) ) )} -> 3456000 | AK26: {=IFERROR( _xlfn.IFS( JiraDataset[[#This Row],[IssueType]] = cfg_type_comment,"SKIP", JiraDataset[[#This Row],[IssueType]] = cfg_type_skip,"SKIP", JiraDataset[[#This Row],[IssueType]] = cfg_type_note,"SKIP" ), cfg_type_workitem )} -> WorkItem
A27: Medium | B27: task | C27: Permission Editor UI | E27: Create admin UI to manage permissions | F27: =Config!$G$4 -> JITTP Version 1 | G27: Bob B | H27: Frontend | J27: 1 | K27: abc | L27: 3d | M27: 25 | N27: 23 | P27: =IF(JiraDataset[[#This Row],[IssueType]]="Epic",JiraDataset[[#This Row],[Summary]],"") | AE27: =IF(JiraDataset[[#This Row],[RowType]]=cfg_type_skip,"",IFERROR(VLOOKUP(JiraDataset[[#This Row],[Sprint Name]], Config!$D$4:$E$9, 2, FALSE), "")) | AF27: =IF(JiraDataset[[#This Row],[RowType]]=cfg_type_skip,"",_xlfn.XLOOKUP("Creation Marker", CfgAutofieldValues[Name], CfgAutofieldValues[Value])) -> jt-imported | AG27: =IF(JiraDataset[[#This Row],[RowType]]=cfg_type_skip,"",_xlfn.XLOOKUP("Feature Pod Label", CfgAutofieldValues[Name], CfgAutofieldValues[Value])) -> ft-group-1 | AH27: =IF(JiraDataset[[#This Row],[RowType]]=cfg_type_skip,"",IFERROR(VLOOKUP(JiraDataset[[#This Row],[Assignee.Name]], Config!$A$4:$B$24, 2, FALSE), "")) -> someID | AI27: =IF(JiraDataset[[#This Row],[RowType]]=cfg_type_skip,"",_xlfn.XLOOKUP("jira.project.key", CfgAutofieldValues[Name], CfgAutofieldValues[Value])) -> PRJ_KEY | AJ27: {=IF( JiraDataset[[#This Row],[RowType]]=cfg_type_skip, "", _xlfn.LET( _xlpm.p, _xlfn.TEXTSPLIT(JiraDataset[[#This Row],[Estimate]], " "), _xlpm.getVal, _xlfn.LAMBDA(_xlpm.u, IFERROR(VALUE(LEFT(_xlfn._xlws.FILTER(_xlpm.p, RIGHT(_xlpm.p,1)=_xlpm.u), LEN(_xlfn._xlws.FILTER(_xlpm.p, RIGHT(_xlpm.p,1)=_xlpm.u))-1)), 0)), _xlpm.w, _xlpm.getVal("w"), _xlpm.d, _xlpm.getVal("d"), _xlpm.h, _xlpm.getVal("h"), _xlpm.m, _xlpm.getVal("m"), _xlpm.seconds, _xlpm.w*144000 + _xlpm.d*28800 + _xlpm.h*3600 + _xlpm.m*60, IF(_xlpm.seconds=0, "", _xlpm.seconds*60) ) )} -> 5184000 | AK27: {=IFERROR( _xlfn.IFS( JiraDataset[[#This Row],[IssueType]] = cfg_type_comment,"SKIP", JiraDataset[[#This Row],[IssueType]] = cfg_type_skip,"SKIP", JiraDataset[[#This Row],[IssueType]] = cfg_type_note,"SKIP" ), cfg_type_workitem )} -> WorkItem
A28: Highest | B28: bug | C28: Access Denied Bug | E28: Authorized users blocked by guard | F28: =Config!$G$4 -> JITTP Version 1 | G28: joe.grunt | H28: Backend | J28: 1 | K28: abc | L28: 1d | M28: 26 | N28: 23 | P28: =IF(JiraDataset[[#This Row],[IssueType]]="Epic",JiraDataset[[#This Row],[Summary]],"") | AE28: =IF(JiraDataset[[#This Row],[RowType]]=cfg_type_skip,"",IFERROR(VLOOKUP(JiraDataset[[#This Row],[Sprint Name]], Config!$D$4:$E$9, 2, FALSE), "")) | AF28: =IF(JiraDataset[[#This Row],[RowType]]=cfg_type_skip,"",_xlfn.XLOOKUP("Creation Marker", CfgAutofieldValues[Name], CfgAutofieldValues[Value])) -> jt-imported | AG28: =IF(JiraDataset[[#This Row],[RowType]]=cfg_type_skip,"",_xlfn.XLOOKUP("Feature Pod Label", CfgAutofieldValues[Name], CfgAutofieldValues[Value])) -> ft-group-1 | AH28: =IF(JiraDataset[[#This Row],[RowType]]=cfg_type_skip,"",IFERROR(VLOOKUP(JiraDataset[[#This Row],[Assignee.Name]], Config!$A$4:$B$24, 2, FALSE), "")) -> someID | AI28: =IF(JiraDataset[[#This Row],[RowType]]=cfg_type_skip,"",_xlfn.XLOOKUP("jira.project.key", CfgAutofieldValues[Name], CfgAutofieldValues[Value])) -> PRJ_KEY | AJ28: {=IF( JiraDataset[[#This Row],[RowType]]=cfg_type_skip, "", _xlfn.LET( _xlpm.p, _xlfn.TEXTSPLIT(JiraDataset[[#This Row],[Estimate]], " "), _xlpm.getVal, _xlfn.LAMBDA(_xlpm.u, IFERROR(VALUE(LEFT(_xlfn._xlws.FILTER(_xlpm.p, RIGHT(_xlpm.p,1)=_xlpm.u), LEN(_xlfn._xlws.FILTER(_xlpm.p, RIGHT(_xlpm.p,1)=_xlpm.u))-1)), 0)), _xlpm.w, _xlpm.getVal("w"), _xlpm.d, _xlpm.getVal("d"), _xlpm.h, _xlpm.getVal("h"), _xlpm.m, _xlpm.getVal("m"), _xlpm.seconds, _xlpm.w*144000 + _xlpm.d*28800 + _xlpm.h*3600 + _xlpm.m*60, IF(_xlpm.seconds=0, "", _xlpm.seconds*60) ) )} -> 1728000 | AK28: {=IFERROR( _xlfn.IFS( JiraDataset[[#This Row],[IssueType]] = cfg_type_comment,"SKIP", JiraDataset[[#This Row],[IssueType]] = cfg_type_skip,"SKIP", JiraDataset[[#This Row],[IssueType]] = cfg_type_note,"SKIP" ), cfg_type_workitem )} -> WorkItem
A29: Low | B29: sub-task | C29: Unit Tests: Guards | E29: Add unit tests for permission guards | F29: =Config!$G$4 -> JITTP Version 1 | G29: john.doe | H29: Testing | J29: 1 | K29: abc | L29: 6h | M29: 27 | N29: 24 | P29: =IF(JiraDataset[[#This Row],[IssueType]]="Epic",JiraDataset[[#This Row],[Summary]],"") | AE29: =IF(JiraDataset[[#This Row],[RowType]]=cfg_type_skip,"",IFERROR(VLOOKUP(JiraDataset[[#This Row],[Sprint Name]], Config!$D$4:$E$9, 2, FALSE), "")) | AF29: =IF(JiraDataset[[#This Row],[RowType]]=cfg_type_skip,"",_xlfn.XLOOKUP("Creation Marker", CfgAutofieldValues[Name], CfgAutofieldValues[Value])) -> jt-imported | AG29: =IF(JiraDataset[[#This Row],[RowType]]=cfg_type_skip,"",_xlfn.XLOOKUP("Feature Pod Label", CfgAutofieldValues[Name], CfgAutofieldValues[Value])) -> ft-group-1 | AH29: =IF(JiraDataset[[#This Row],[RowType]]=cfg_type_skip,"",IFERROR(VLOOKUP(JiraDataset[[#This Row],[Assignee.Name]], Config!$A$4:$B$24, 2, FALSE), "")) -> someID | AI29: =IF(JiraDataset[[#This Row],[RowType]]=cfg_type_skip,"",_xlfn.XLOOKUP("jira.project.key", CfgAutofieldValues[Name], CfgAutofieldValues[Value])) -> PRJ_KEY | AJ29: {=IF( JiraDataset[[#This Row],[RowType]]=cfg_type_skip, "", _xlfn.LET( _xlpm.p, _xlfn.TEXTSPLIT(JiraDataset[[#This Row],[Estimate]], " "), _xlpm.getVal, _xlfn.LAMBDA(_xlpm.u, IFERROR(VALUE(LEFT(_xlfn._xlws.FILTER(_xlpm.p, RIGHT(_xlpm.p,1)=_xlpm.u), LEN(_xlfn._xlws.FILTER(_xlpm.p, RIGHT(_xlpm.p,1)=_xlpm.u))-1)), 0)), _xlpm.w, _xlpm.getVal("w"), _xlpm.d, _xlpm.getVal("d"), _xlpm.h, _xlpm.getVal("h"), _xlpm.m, _xlpm.getVal("m"), _xlpm.seconds, _xlpm.w*144000 + _xlpm.d*28800 + _xlpm.h*3600 + _xlpm.m*60, IF(_xlpm.seconds=0, "", _xlpm.seconds*60) ) )} -> 1296000 | AK29: {=IFERROR( _xlfn.IFS( JiraDataset[[#This Row],[IssueType]] = cfg_type_comment,"SKIP", JiraDataset[[#This Row],[IssueType]] = cfg_type_skip,"SKIP", JiraDataset[[#This Row],[IssueType]] = cfg_type_note,"SKIP" ), cfg_type_workitem )} -> WorkItem
A30: High | B30: epic | C30: Localization & Accessibility | E30: Internationalization and a11y | F30: =Config!$G$4 -> JITTP Version 1 | G30: jane.smith | H30: Localization | J30: 1 | K30: abc | L30: 1w | M30: 28 | N30: 17 | P30: =IF(JiraDataset[[#This Row],[IssueType]]="Epic",JiraDataset[[#This Row],[Summary]],"") -> Localization & Accessibility | AE30: =IF(JiraDataset[[#This Row],[RowType]]=cfg_type_skip,"",IFERROR(VLOOKUP(JiraDataset[[#This Row],[Sprint Name]], Config!$D$4:$E$9, 2, FALSE), "")) | AF30: =IF(JiraDataset[[#This Row],[RowType]]=cfg_type_skip,"",_xlfn.XLOOKUP("Creation Marker", CfgAutofieldValues[Name], CfgAutofieldValues[Value])) -> jt-imported | AG30: =IF(JiraDataset[[#This Row],[RowType]]=cfg_type_skip,"",_xlfn.XLOOKUP("Feature Pod Label", CfgAutofieldValues[Name], CfgAutofieldValues[Value])) -> ft-group-1 | AH30: =IF(JiraDataset[[#This Row],[RowType]]=cfg_type_skip,"",IFERROR(VLOOKUP(JiraDataset[[#This Row],[Assignee.Name]], Config!$A$4:$B$24, 2, FALSE), "")) -> someID | AI30: =IF(JiraDataset[[#This Row],[RowType]]=cfg_type_skip,"",_xlfn.XLOOKUP("jira.project.key", CfgAutofieldValues[Name], CfgAutofieldValues[Value])) -> PRJ_KEY | AJ30: {=IF( JiraDataset[[#This Row],[RowType]]=cfg_type_skip, "", _xlfn.LET( _xlpm.p, _xlfn.TEXTSPLIT(JiraDataset[[#This Row],[Estimate]], " "), _xlpm.getVal, _xlfn.LAMBDA(_xlpm.u, IFERROR(VALUE(LEFT(_xlfn._xlws.FILTER(_xlpm.p, RIGHT(_xlpm.p,1)=_xlpm.u), LEN(_xlfn._xlws.FILTER(_xlpm.p, RIGHT(_xlpm.p,1)=_xlpm.u))-1)), 0)), _xlpm.w, _xlpm.getVal("w"), _xlpm.d, _xlpm.getVal("d"), _xlpm.h, _xlpm.getVal("h"), _xlpm.m, _xlpm.getVal("m"), _xlpm.seconds, _xlpm.w*144000 + _xlpm.d*28800 + _xlpm.h*3600 + _xlpm.m*60, IF(_xlpm.seconds=0, "", _xlpm.seconds*60) ) )} -> 8640000 | AK30: {=IFERROR( _xlfn.IFS( JiraDataset[[#This Row],[IssueType]] = cfg_type_comment,"SKIP", JiraDataset[[#This Row],[IssueType]] = cfg_type_skip,"SKIP", JiraDataset[[#This Row],[IssueType]] = cfg_type_note,"SKIP" ), cfg_type_workitem )} -> WorkItem
A31: Medium | B31: story | C31: Language Packs | E31: Ship EN/FR/DE language packs | F31: =Config!$G$4 -> JITTP Version 1 | G31: Alice A | H31: Localization | J31: 1 | K31: abc | L31: 3d | M31: 29 | N31: 28 | P31: =IF(JiraDataset[[#This Row],[IssueType]]="Epic",JiraDataset[[#This Row],[Summary]],"") | AE31: =IF(JiraDataset[[#This Row],[RowType]]=cfg_type_skip,"",IFERROR(VLOOKUP(JiraDataset[[#This Row],[Sprint Name]], Config!$D$4:$E$9, 2, FALSE), "")) | AF31: =IF(JiraDataset[[#This Row],[RowType]]=cfg_type_skip,"",_xlfn.XLOOKUP("Creation Marker", CfgAutofieldValues[Name], CfgAutofieldValues[Value])) -> jt-imported | AG31: =IF(JiraDataset[[#This Row],[RowType]]=cfg_type_skip,"",_xlfn.XLOOKUP("Feature Pod Label", CfgAutofieldValues[Name], CfgAutofieldValues[Value])) -> ft-group-1 | AH31: =IF(JiraDataset[[#This Row],[RowType]]=cfg_type_skip,"",IFERROR(VLOOKUP(JiraDataset[[#This Row],[Assignee.Name]], Config!$A$4:$B$24, 2, FALSE), "")) -> someID | AI31: =IF(JiraDataset[[#This Row],[RowType]]=cfg_type_skip,"",_xlfn.XLOOKUP("jira.project.key", CfgAutofieldValues[Name], CfgAutofieldValues[Value])) -> PRJ_KEY | AJ31: {=IF( JiraDataset[[#This Row],[RowType]]=cfg_type_skip, "", _xlfn.LET( _xlpm.p, _xlfn.TEXTSPLIT(JiraDataset[[#This Row],[Estimate]], " "), _xlpm.getVal, _xlfn.LAMBDA(_xlpm.u, IFERROR(VALUE(LEFT(_xlfn._xlws.FILTER(_xlpm.p, RIGHT(_xlpm.p,1)=_xlpm.u), LEN(_xlfn._xlws.FILTER(_xlpm.p, RIGHT(_xlpm.p,1)=_xlpm.u))-1)), 0)), _xlpm.w, _xlpm.getVal("w"), _xlpm.d, _xlpm.getVal("d"), _xlpm.h, _xlpm.getVal("h"), _xlpm.m, _xlpm.getVal("m"), _xlpm.seconds, _xlpm.w*144000 + _xlpm.d*28800 + _xlpm.h*3600 + _xlpm.m*60, IF(_xlpm.seconds=0, "", _xlpm.seconds*60) ) )} -> 5184000 | AK31: {=IFERROR( _xlfn.IFS( JiraDataset[[#This Row],[IssueType]] = cfg_type_comment,"SKIP", JiraDataset[[#This Row],[IssueType]] = cfg_type_skip,"SKIP", JiraDataset[[#This Row],[IssueType]] = cfg_type_note,"SKIP" ), cfg_type_workitem )} -> WorkItem
