Workbook
Name cfg_labels_ft_label: 'Config - Basic'!$B$6
Name cfg_labels_ft_name: 'Config - Basic'!$B$6
Name cfg_labels_imported: 'Config - Basic'!$B$5
Name cfg_projectKey: 'Config - Basic'!$B$4
Name cfg_type_comment: 'Config - Factory'!$I$4
Name cfg_type_note: 'Config - Factory'!$I$6
Name cfg_type_skip: 'Config - Factory'!$I$5
Name cfg_type_workitem: 'Config - Factory'!$I$7
Name CfgIssueTypeList: 'Config - Factory'!$A$4:$A$24

Sheet Dataset
A1: Priority | B1: IssueType | C1: Summary | D1: Issue Key | E1: Description | F1: FixVersion | G1: Assignee.Name | H1: Component | I1: Sprint Name | J1: Estimate | K1: Issue ID | L1: Parent | M1: Epic Link | N1: Epic Name | O1: Child-Issue | P1: Child-Issue1 | Q1: Child-Issue2 | R1: Labels | S1: Labels1 | T1: Labels2 | U1: Labels3 | V1: Labels4 | W1: Labels5 | X1: Labels6 | Y1: Labels7 | Z1: Labels8 | AA1: Labels9 | AB1: Labels10 | AC1: Sprint | AD1: Labels0001 | AE1: Labels0002 | AF1: Assignee | AG1: Project Key | AH1: OrigEst | AI1: RowType | AJ1: Note
B2: Note | C2: FORMULA HOLDER | E2: DO NOT DELETE, IT'S USED FOR THE CALCULATED COLUMNS AND AS REFERENCE IN CASE OF MISSING FORMULA | N2: =IF(JiraDataset[[#This Row],[IssueType]]="Epic",JiraDataset[[#This Row],[Summary]],"") | AC2: =IF(JiraDataset[[#This Row],[RowType]]=cfg_type_skip,"",IFERROR(VLOOKUP(JiraDataset[[#This Row],[Sprint Name]], 'Config - Mappings'!$G$4:$H$8, 2, FALSE), "")) | AD2: =IF(JiraDataset[[#This Row],[RowType]]=cfg_type_skip,"",_xlfn.XLOOKUP("Creation Marker", CfgMisc[Name], CfgMisc[Value],"",1)) | AE2: =IF(JiraDataset[[#This Row],[RowType]]=cfg_type_skip,"",_xlfn.XLOOKUP("Work Group", CfgMisc[Name], CfgMisc[Value],"",1)) | AF2: =IF(JiraDataset[[#This Row],[RowType]]=cfg_type_skip,"",IFERROR(VLOOKUP(JiraDataset[[#This Row],[Assignee.Name]], 'Config - Mappings'!$A$4:$B$26, 2, FALSE), "")) | AG2: =IF(JiraDataset[[#This Row],[RowType]]=cfg_type_skip,"",_xlfn.XLOOKUP("jira.project.key", CfgBasic[Name], CfgBasic[Value])) | AH2: {=IF( JiraDataset[[#This Row],[RowType]]=cfg_type_skip, "", _xlfn.LET( _xlpm.p, _xlfn.TEXTSPLIT(JiraDataset[[#This Row],[Estimate]], " "), _xlpm.getVal, _xlfn.LAMBDA(_xlpm.u, IFERROR(VALUE(LEFT(_xlfn._xlws.FILTER(_xlpm.p, RIGHT(_xlpm.p,1)=_xlpm.u), LEN(_xlfn._xlws.FILTER(_xlpm.p, RIGHT(_xlpm.p,1)=_xlpm.u))-1)), 0)), _xlpm.w, _xlpm.getVal("w"), _xlpm.d, _xlpm.getVal("d"), _xlpm.h, _xlpm.getVal("h"), _xlpm.m, _xlpm.getVal("m"), _xlpm.seconds, _xlpm.w*144000 + _xlpm.d*28800 + _xlpm.h*3600 + _xlpm.m*60, IF(_xlpm.seconds=0, "", _xlpm.seconds*60) ) )} | AI2: {=IFERROR( _xlfn.IFS( JiraDataset[[#This Row],[IssueType]] = cfg_type_comment,"SKIP", JiraDataset[[#This Row],[IssueType]] = cfg_type_skip,"SKIP", JiraDataset[[#This Row],[IssueType]] = cfg_type_note,"SKIP" ), cfg_type_workitem )} -> SKIP
A3: High | B3: initiative | C3: Digital Transformation Program | E3: Top-level initiative coordinating cross-domain work | F3: JITTP Version 1 | G3: joe.grunt | J3: 2w | K3: 1 | N3: =IF(JiraDataset[[#This Row],[IssueType]]="Epic",JiraDataset[[#This Row],[Summary]],"") | R3: First Label | S3: Second Label; Third Label | T3: Another Label | AC3: =IF(JiraDataset[[#This Row],[RowType]]=cfg_type_skip,"",IFERROR(VLOOKUP(JiraDataset[[#This Row],[Sprint Name]], 'Config - Mappings'!$G$4:$H$8, 2, FALSE), "")) | AD3: =IF(JiraDataset[[#This Row],[RowType]]=cfg_type_skip,"",_xlfn.XLOOKUP("Creation Marker", CfgMisc[Name], CfgMisc[Value],"",1)) -> imported | AE3: =IF(JiraDataset[[#This Row],[RowType]]=cfg_type_skip,"",_xlfn.XLOOKUP("Work Group", CfgMisc[Name], CfgMisc[Value],"",1)) -> pod_test | AF3: =IF(JiraDataset[[#This Row],[RowType]]=cfg_type_skip,"",IFERROR(VLOOKUP(JiraDataset[[#This Row],[Assignee.Name]], 'Config - Mappings'!$A$4:$B$26, 2, FALSE), "")) -> 712020:09876543212345678901 | AG3: =IF(JiraDataset[[#This Row],[RowType]]=cfg_type_skip,"",_xlfn.XLOOKUP("jira.project.key", CfgBasic[Name], CfgBasic[Value])) -> JITTP2 | AH3: {=IF( JiraDataset[[#This Row],[RowType]]=cfg_type_skip, "", _xlfn.LET( _xlpm.p, _xlfn.TEXTSPLIT(JiraDataset[[#This Row],[Estimate]], " "), _xlpm.getVal, _xlfn.LAMBDA(_xlpm.u, IFERROR(VALUE(LEFT(_xlfn._xlws.FILTER(_xlpm.p, RIGHT(_xlpm.p,1)=_xlpm.u), LEN(_xlfn._xlws.FILTER(_xlpm.p, RIGHT(_xlpm.p,1)=_xlpm.u))-1)), 0)), _xlpm.w, _xlpm.getVal("w"), _xlpm.d, _xlpm.getVal("d"), _xlpm.h, _xlpm.getVal("h"), _xlpm.m, _xlpm.getVal("m"), _xlpm.seconds, _xlpm.w*144000 + _xlpm.d*28800 + _xlpm.h*3600 + _xlpm.m*60, IF(_xlpm.seconds=0, "", _xlpm.seconds*60) ) )} -> 17280000 | AI3: {=IFERROR( _xlfn.IFS( JiraDataset[[#This Row],[IssueType]] = cfg_type_comment,"SKIP", JiraDataset[[#This Row],[IssueType]] = cfg_type_skip,"SKIP", JiraDataset[[#This Row],[IssueType]] = cfg_type_note,"SKIP" ), cfg_type_workitem )} -> WorkItem
A4: Medium | B4: epic | C4: Customer Onboarding Revamp | E4: Improve first-time user experience and activation | F4: JITTP Version 1 | G4: john.doe | H4: Product | J4: 1w | K4: 2 | L4: 1 | N4: =IF(JiraDataset[[#This Row],[IssueType]]="Epic",JiraDataset[[#This Row],[Summary]],"") -> Customer Onboarding Revamp | AC4: =IF(JiraDataset[[#This Row],[RowType]]=cfg_type_skip,"",IFERROR(VLOOKUP(JiraDataset[[#This Row],[Sprint Name]], 'Config - Mappings'!$G$4:$H$8, 2, FALSE), "")) | AD4: =IF(JiraDataset[[#This Row],[RowType]]=cfg_type_skip,"",_xlfn.XLOOKUP("Creation Marker", CfgMisc[Name], CfgMisc[Value],"",1)) -> imported | AE4: =IF(JiraDataset[[#This Row],[RowType]]=cfg_type_skip,"",_xlfn.XLOOKUP("Work Group", CfgMisc[Name], CfgMisc[Value],"",1)) -> pod_test | AF4: =IF(JiraDataset[[#This Row],[RowType]]=cfg_type_skip,"",IFERROR(VLOOKUP(JiraDataset[[#This Row],[Assignee.Name]], 'Config - Mappings'!$A$4:$B$26, 2, FALSE), "")) -> 712020:09876543212345678902 | AG4: =IF(JiraDataset[[#This Row],[RowType]]=cfg_type_skip,"",_xlfn.XLOOKUP("jira.project.key", CfgBasic[Name], CfgBasic[Value])) -> JITTP2 | AH4: {=IF( JiraDataset[[#This Row],[RowType]]=cfg_type_skip, "", _xlfn.LET( _xlpm.p, _xlfn.TEXTSPLIT(JiraDataset[[#This Row],[Estimate]], " "), _xlpm.getVal, _xlfn.LAMBDA(_xlpm.u, IFERROR(VALUE(LEFT(_xlfn._xlws.FILTER(_xlpm.p, RIGHT(_xlpm.p,1)=_xlpm.u), LEN(_xlfn._xlws.FILTER(_xlpm.p, RIGHT(_xlpm.p,1)=_xlpm.u))-1)), 0)), _xlpm.w, _xlpm.getVal("w"), _xlpm.d, _xlpm.getVal("d"), _xlpm.h, _xlpm.getVal("h"), _xlpm.m, _xlpm.getVal("m"), _xlpm.seconds, _xlpm.w*144000 + _xlpm.d*28800 + _xlpm.h*3600 + _xlpm.m*60, IF(_xlpm.seconds=0, "", _xlpm.seconds*60) ) )} -> 8640000 | AI4: {=IFERROR( _xlfn.IFS( JiraDataset[[#This Row],[IssueType]] = cfg_type_comment,"SKIP", JiraDataset[[#This Row],[IssueType]] = cfg_type_skip,"SKIP", JiraDataset[[#This Row],[IssueType]] = cfg_type_note,"SKIP" ), cfg_type_workitem )} -> WorkItem
A5: Highest | B5: story | C5: Design Welcome Flow | E5: Create wireframes and copy for welcome steps | F5: JITTP Version 1 | G5: jane.smith | H5: UX | J5: 3d | K5: 3 | L5: 2 | N5: =IF(JiraDataset[[#This Row],[IssueType]]="Epic",JiraDataset[[#This Row],[Summary]],"") | AC5: =IF(JiraDataset[[#This Row],[RowType]]=cfg_type_skip,"",IFERROR(VLOOKUP(JiraDataset[[#This Row],[Sprint Name]], 'Config - Mappings'!$G$4:$H$8, 2, FALSE), "")) | AD5: =IF(JiraDataset[[#This Row],[RowType]]=cfg_type_skip,"",_xlfn.XLOOKUP("Creation Marker", CfgMisc[Name], CfgMisc[Value],"",1)) -> imported | AE5: =IF(JiraDataset[[#This Row],[RowType]]=cfg_type_skip,"",_xlfn.XLOOKUP("Work Group", CfgMisc[Name], CfgMisc[Value],"",1)) -> pod_test | AF5: =IF(JiraDataset[[#This Row],[RowType]]=cfg_type_skip,"",IFERROR(VLOOKUP(JiraDataset[[#This Row],[Assignee.Name]], 'Config - Mappings'!$A$4:$B$26, 2, FALSE), "")) -> 712020:09876543212345678903 | AG5: =IF(JiraDataset[[#This Row],[RowType]]=cfg_type_skip,"",_xlfn.XLOOKUP("jira.project.key", CfgBasic[Name], CfgBasic[Value])) -> JITTP2 | AH5: {=IF( JiraDataset[[#This Row],[RowType]]=cfg_type_skip, "", _xlfn.LET( _xlpm.p, _xlfn.TEXTSPLIT(JiraDataset[[#This Row],[Estimate]], " "), _xlpm.getVal, _xlfn.LAMBDA(_xlpm.u, IFERROR(VALUE(LEFT(_xlfn._xlws.FILTER(_xlpm.p, RIGHT(_xlpm.p,1)=_xlpm.u), LEN(_xlfn._xlws.FILTER(_xlpm.p, RIGHT(_xlpm.p,1)=_xlpm.u))-1)), 0)), _xlpm.w, _xlpm.getVal("w"), _xlpm.d, _xlpm.getVal("d"), _xlpm.h, _xlpm.getVal("h"), _xlpm.m, _xlpm.getVal("m"), _xlpm.seconds, _xlpm.w*144000 + _xlpm.d*28800 + _xlpm.h*3600 + _xlpm.m*60, IF(_xlpm.seconds=0, "", _xlpm.seconds*60) ) )} -> 5184000 | AI5: {=IFERROR( _xlfn.IFS( JiraDataset[[#This Row],[IssueType]] = cfg_type_comment,"SKIP", JiraDataset[[#This Row],[IssueType]] = cfg_type_skip,"SKIP", JiraDataset[[#This Row],[IssueType]] = cfg_type_note,"SKIP" ), cfg_type_workitem )} -> WorkItem
A6: High | B6: task | C6: Implement Welcome Screens | E6: Build front-end for multi-step welcome | F6: JITTP Version 1 | G6: Alice A | H6: Frontend | J6: 4d | K6: 4 | L6: 2 | N6: =IF(JiraDataset[[#This Row],[IssueType]]="Epic",JiraDataset[[#This Row],[Summary]],"") | AC6: =IF(JiraDataset[[#This Row],[RowType]]=cfg_type_skip,"",IFERROR(VLOOKUP(JiraDataset[[#This Row],[Sprint Name]], 'Config - Mappings'!$G$4:$H$8, 2, FALSE), "")) | AD6: =IF(JiraDataset[[#This Row],[RowType]]=cfg_type_skip,"",_xlfn.XLOOKUP("Creation Marker", CfgMisc[Name], CfgMisc[Value],"",1)) -> imported | AE6: =IF(JiraDataset[[#This Row],[RowType]]=cfg_type_skip,"",_xlfn.XLOOKUP("Work Group", CfgMisc[Name], CfgMisc[Value],"",1)) -> pod_test | AF6: =IF(JiraDataset[[#This Row],[RowType]]=cfg_type_skip,"",IFERROR(VLOOKUP(JiraDataset[[#This Row],[Assignee.Name]], 'Config - Mappings'!$A$4:$B$26, 2, FALSE), "")) -> 712020:09876543212345678904 | AG6: =IF(JiraDataset[[#This Row],[RowType]]=cfg_type_skip,"",_xlfn.XLOOKUP("jira.project.key", CfgBasic[Name], CfgBasic[Value])) -> JITTP2 | AH6: {=IF( JiraDataset[[#This Row],[RowType]]=cfg_type_skip, "", _xlfn.LET( _xlpm.p, _xlfn.TEXTSPLIT(JiraDataset[[#This Row],[Estimate]], " "), _xlpm.getVal, _xlfn.LAMBDA(_xlpm.u, IFERROR(VALUE(LEFT(_xlfn._xlws.FILTER(_xlpm.p, RIGHT(_xlpm.p,1)=_xlpm.u), LEN(_xlfn._xlws.FILTER(_xlpm.p, RIGHT(_xlpm.p,1)=_xlpm.u))-1)), 0)), _xlpm.w, _xlpm.getVal("w"), _xlpm.d, _xlpm.getVal("d"), _xlpm.h, _xlpm.getVal("h"), _xlpm.m, _xlpm.getVal("m"), _xlpm.seconds, _xlpm.w*144000 + _xlpm.d*28800 + _xlpm.h*3600 + _xlpm.m*60, IF(_xlpm.seconds=0, "", _xlpm.seconds*60) ) )} -> 6912000 | AI6: {=IFERROR( _xlfn.IFS( JiraDataset[[#This Row],[IssueType]] = cfg_type_comment,"SKIP", JiraDataset[[#This Row],[IssueType]] = cfg_type_skip,"SKIP", JiraDataset[[#This Row],[IssueType]] = cfg_type_note,"SKIP" ), cfg_type_workitem )} -> WorkItem
A7: Low | B7: bug | C7: Fix Broken Skip Button | E7: Skip button unresponsive on step 2 | F7: JITTP Version 1 | G7: Bob B | H7: Frontend | J7: 6h | K7: 5 | L7: 2 | N7: =IF(JiraDataset[[#This Row],[IssueType]]="Epic",JiraDataset[[#This Row],[Summary]],"") | AC7: =IF(JiraDataset[[#This Row],[RowType]]=cfg_type_skip,"",IFERROR(VLOOKUP(JiraDataset[[#This Row],[Sprint Name]], 'Config - Mappings'!$G$4:$H$8, 2, FALSE), "")) | AD7: =IF(JiraDataset[[#This Row],[RowType]]=cfg_type_skip,"",_xlfn.XLOOKUP("Creation Marker", CfgMisc[Name], CfgMisc[Value],"",1)) -> imported | AE7: =IF(JiraDataset[[#This Row],[RowType]]=cfg_type_skip,"",_xlfn.XLOOKUP("Work Group", CfgMisc[Name], CfgMisc[Value],"",1)) -> pod_test | AF7: =IF(JiraDataset[[#This Row],[RowType]]=cfg_type_skip,"",IFERROR(VLOOKUP(JiraDataset[[#This Row],[Assignee.Name]], 'Config - Mappings'!$A$4:$B$26, 2, FALSE), "")) -> 712020:09876543212345678905 | AG7: =IF(JiraDataset[[#This Row],[RowType]]=cfg_type_skip,"",_xlfn.XLOOKUP("jira.project.key", CfgBasic[Name], CfgBasic[Value])) -> JITTP2 | AH7: {=IF( JiraDataset[[#This Row],[RowType]]=cfg_type_skip, "", _xlfn.LET( _xlpm.p, _xlfn.TEXTSPLIT(JiraDataset[[#This Row],[Estimate]], " "), _xlpm.getVal, _xlfn.LAMBDA(_xlpm.u, IFERROR(VALUE(LEFT(_xlfn._xlws.FILTER(_xlpm.p, RIGHT(_xlpm.p,1)=_xlpm.u), LEN(_xlfn._xlws.FILTER(_xlpm.p, RIGHT(_xlpm.p,1)=_xlpm.u))-1)), 0)), _xlpm.w, _xlpm.getVal("w"), _xlpm.d, _xlpm.getVal("d"), _xlpm.h, _xlpm.getVal("h"), _xlpm.m, _xlpm.getVal("m"), _xlpm.seconds, _xlpm.w*144000 + _xlpm.d*28800 + _xlpm.h*3600 + _xlpm.m*60, IF(_xlpm.seconds=0, "", _xlpm.seconds*60) ) )} -> 1296000 | AI7: {=IFERROR( _xlfn.IFS( JiraDataset[[#This Row],[IssueType]] = cfg_type_comment,"SKIP", JiraDataset[[#This Row],[IssueType]] = cfg_type_skip,"SKIP", JiraDataset[[#This Row],[IssueType]] = cfg_type_note,"SKIP" ), cfg_type_workitem )} -> WorkItem
A8: Lowest | B8: sub-task | C8: Unit Tests: Welcome Flow | E8: Cover edge cases for welcome logic | F8: JITTP Version 1 | G8: joe.grunt | H8: Testing | J8: 1d | K8: 6 | L8: 3 | N8: =IF(JiraDataset[[#This Row],[IssueType]]="Epic",JiraDataset[[#This Row],[Summary]],"") | AC8: =IF(JiraDataset[[#This Row],[RowType]]=cfg_type_skip,"",IFERROR(VLOOKUP(JiraDataset[[#This Row],[Sprint Name]], 'Config - Mappings'!$G$4:$H$8, 2, FALSE), "")) | AD8: =IF(JiraDataset[[#This Row],[RowType]]=cfg_type_skip,"",_xlfn.XLOOKUP("Creation Marker", CfgMisc[Name], CfgMisc[Value],"",1)) -> imported | AE8: =IF(JiraDataset[[#This Row],[RowType]]=cfg_type_skip,"",_xlfn.XLOOKUP("Work Group", CfgMisc[Name], CfgMisc[Value],"",1)) -> pod_test | AF8: =IF(JiraDataset[[#This Row],[RowType]]=cfg_type_skip,"",IFERROR(VLOOKUP(JiraDataset[[#This Row],[Assignee.Name]], 'Config - Mappings'!$A$4:$B$26, 2, FALSE), "")) -> 712020:09876543212345678901 | AG8: =IF(JiraDataset[[#This Row],[RowType]]=cfg_type_skip,"",_xlfn.XLOOKUP("jira.project.key", CfgBasic[Name], CfgBasic[Value])) -> JITTP2 | AH8: {=IF( JiraDataset[[#This Row],[RowType]]=cfg_type_skip, "", _xlfn.LET( _xlpm.p, _xlfn.TEXTSPLIT(JiraDataset[[#This Row],[Estimate]], " "), _xlpm.getVal, _xlfn.LAMBDA(_xlpm.u, IFERROR(VALUE(LEFT(_xlfn._xlws.FILTER(_xlpm.p, RIGHT(_xlpm.p,1)=_xlpm.u), LEN(_xlfn._xlws.FILTER(_xlpm.p, RIGHT(_xlpm.p,1)=_xlpm.u))-1)), 0)), _xlpm.w, _xlpm.getVal("w"), _xlpm.d, _xlpm.getVal("d"), _xlpm.h, _xlpm.getVal("h"), _xlpm.m, _xlpm.getVal("m"), _xlpm.seconds, _xlpm.w*144000 + _xlpm.d*28800 + _xlpm.h*3600 + _xlpm.m*60, IF(_xlpm.seconds=0, "", _xlpm.seconds*60) ) )} -> 1728000 | AI8: {=IFERROR( _xlfn.IFS( JiraDataset[[#This Row],[IssueType]] = cfg_type_comment,"SKIP", JiraDataset[[#This Row],[IssueType]] = cfg_type_skip,"SKIP", JiraDataset[[#This Row],[IssueType]] = cfg_type_note,"SKIP" ), cfg_type_workitem )} -> WorkItem
A9: Highest | B9: Task | C9: Authentication & Accounts | E9: Modernize auth | F9: JITTP Version 1 | G9: jane.smith | H9: Security | J9: 1d | K9: 7 | L9: 2 | N9: =IF(JiraDataset[[#This Row],[IssueType]]="Epic",JiraDataset[[#This Row],[Summary]],"") | AC9: =IF(JiraDataset[[#This Row],[RowType]]=cfg_type_skip,"",IFERROR(VLOOKUP(JiraDataset[[#This Row],[Sprint Name]], 'Config - Mappings'!$G$4:$H$8, 2, FALSE), "")) | AD9: =IF(JiraDataset[[#This Row],[RowType]]=cfg_type_skip,"",_xlfn.XLOOKUP("Creation Marker", CfgMisc[Name], CfgMisc[Value],"",1)) -> imported | AE9: =IF(JiraDataset[[#This Row],[RowType]]=cfg_type_skip,"",_xlfn.XLOOKUP("Work Group", CfgMisc[Name], CfgMisc[Value],"",1)) -> pod_test | AF9: =IF(JiraDataset[[#This Row],[RowType]]=cfg_type_skip,"",IFERROR(VLOOKUP(JiraDataset[[#This Row],[Assignee.Name]], 'Config - Mappings'!$A$4:$B$26, 2, FALSE), "")) -> 712020:09876543212345678903 | AG9: =IF(JiraDataset[[#This Row],[RowType]]=cfg_type_skip,"",_xlfn.XLOOKUP("jira.project.key", CfgBasic[Name], CfgBasic[Value])) -> JITTP2 | AH9: {=IF( JiraDataset[[#This Row],[RowType]]=cfg_type_skip, "", _xlfn.LET( _xlpm.p, _xlfn.TEXTSPLIT(JiraDataset[[#This Row],[Estimate]], " "), _xlpm.getVal, _xlfn.LAMBDA(_xlpm.u, IFERROR(VALUE(LEFT(_xlfn._xlws.FILTER(_xlpm.p, RIGHT(_xlpm.p,1)=_xlpm.u), LEN(_xlfn._xlws.FILTER(_xlpm.p, RIGHT(_xlpm.p,1)=_xlpm.u))-1)), 0)), _xlpm.w, _xlpm.getVal("w"), _xlpm.d, _xlpm.getVal("d"), _xlpm.h, _xlpm.getVal("h"), _xlpm.m, _xlpm.getVal("m"), _xlpm.seconds, _xlpm.w*144000 + _xlpm.d*28800 + _xlpm.h*3600 + _xlpm.m*60, IF(_xlpm.seconds=0, "", _xlpm.seconds*60) ) )} -> 1728000 | AI9: {=IFERROR( _xlfn.IFS( JiraDataset[[#This Row],[IssueType]] = cfg_type_comment,"SKIP", JiraDataset[[#This Row],[IssueType]] = cfg_type_skip,"SKIP", JiraDataset[[#This Row],[IssueType]] = cfg_type_note,"SKIP" ), cfg_type_workitem )} -> WorkItem
A10: High | B10: story | C10: SSO Integration | E10: Add OIDC SSO with corporate IdP | F10: JITTP Version 1 | G10: jane.smith | H10: Backend | J10: 3d | K10: 8 | L10: 7 | N10: =IF(JiraDataset[[#This Row],[IssueType]]="Epic",JiraDataset[[#This Row],[Summary]],"") | AC10: =IF(JiraDataset[[#This Row],[RowType]]=cfg_type_skip,"",IFERROR(VLOOKUP(JiraDataset[[#This Row],[Sprint Name]], 'Config - Mappings'!$G$4:$H$8, 2, FALSE), "")) | AD10: =IF(JiraDataset[[#This Row],[RowType]]=cfg_type_skip,"",_xlfn.XLOOKUP("Creation Marker", CfgMisc[Name], CfgMisc[Value],"",1)) -> imported | AE10: =IF(JiraDataset[[#This Row],[RowType]]=cfg_type_skip,"",_xlfn.XLOOKUP("Work Group", CfgMisc[Name], CfgMisc[Value],"",1)) -> pod_test | AF10: =IF(JiraDataset[[#This Row],[RowType]]=cfg_type_skip,"",IFERROR(VLOOKUP(JiraDataset[[#This Row],[Assignee.Name]], 'Config - Mappings'!$A$4:$B$26, 2, FALSE), "")) -> 712020:09876543212345678903 | AG10: =IF(JiraDataset[[#This Row],[RowType]]=cfg_type_skip,"",_xlfn.XLOOKUP("jira.project.key", CfgBasic[Name], CfgBasic[Value])) -> JITTP2 | AH10: {=IF( JiraDataset[[#This Row],[RowType]]=cfg_type_skip, "", _xlfn.LET( _xlpm.p, _xlfn.TEXTSPLIT(JiraDataset[[#This Row],[Estimate]], " "), _xlpm.getVal, _xlfn.LAMBDA(_xlpm.u, IFERROR(VALUE(LEFT(_xlfn._xlws.FILTER(_xlpm.p, RIGHT(_xlpm.p,1)=_xlpm.u), LEN(_xlfn._xlws.FILTER(_xlpm.p, RIGHT(_xlpm.p,1)=_xlpm.u))-1)), 0)), _xlpm.w, _xlpm.getVal("w"), _xlpm.d, _xlpm.getVal("d"), _xlpm.h, _xlpm.getVal("h"), _xlpm.m, _xlpm.getVal("m"), _xlpm.seconds, _xlpm.w*144000 + _xlpm.d*28800 + _xlpm.h*3600 + _xlpm.m*60, IF(_xlpm.seconds=0, "", _xlpm.seconds*60) ) )} -> 5184000 | AI10: {=IFERROR( _xlfn.IFS( JiraDataset[[#This Row],[IssueType]] = cfg_type_comment,"SKIP", JiraDataset[[#This Row],[IssueType]] = cfg_type_skip,"SKIP", JiraDataset[[#This Row],[IssueType]] = cfg_type_note,"SKIP" ), cfg_type_workitem )} -> WorkItem
A11: Medium | B11: task | C11: Password Reset Flow | E11: Implement secure token-based reset | F11: JITTP Version 1 | G11: Alice A | H11: Backend | J11: 2d | K11: 9 | L11: 7 | N11: =IF(JiraDataset[[#This Row],[IssueType]]="Epic",JiraDataset[[#This Row],[Summary]],"") | AC11: =IF(JiraDataset[[#This Row],[RowType]]=cfg_type_skip,"",IFERROR(VLOOKUP(JiraDataset[[#This Row],[Sprint Name]], 'Config - Mappings'!$G$4:$H$8, 2, FALSE), "")) | AD11: =IF(JiraDataset[[#This Row],[RowType]]=cfg_type_skip,"",_xlfn.XLOOKUP("Creation Marker", CfgMisc[Name], CfgMisc[Value],"",1)) -> imported | AE11: =IF(JiraDataset[[#This Row],[RowType]]=cfg_type_skip,"",_xlfn.XLOOKUP("Work Group", CfgMisc[Name], CfgMisc[Value],"",1)) -> pod_test | AF11: =IF(JiraDataset[[#This Row],[RowType]]=cfg_type_skip,"",IFERROR(VLOOKUP(JiraDataset[[#This Row],[Assignee.Name]], 'Config - Mappings'!$A$4:$B$26, 2, FALSE), "")) -> 712020:09876543212345678904 | AG11: =IF(JiraDataset[[#This Row],[RowType]]=cfg_type_skip,"",_xlfn.XLOOKUP("jira.project.key", CfgBasic[Name], CfgBasic[Value])) -> JITTP2 | AH11: {=IF( JiraDataset[[#This Row],[RowType]]=cfg_type_skip, "", _xlfn.LET( _xlpm.p, _xlfn.TEXTSPLIT(JiraDataset[[#This Row],[Estimate]], " "), _xlpm.getVal, _xlfn.LAMBDA(_xlpm.u, IFERROR(VALUE(LEFT(_xlfn._xlws.FILTER(_xlpm.p, RIGHT(_xlpm.p,1)=_xlpm.u), LEN(_xlfn._xlws.FILTER(_xlpm.p, RIGHT(_xlpm.p,1)=_xlpm.u))-1)), 0)), _xlpm.w, _xlpm.getVal("w"), _xlpm.d, _xlpm.getVal("d"), _xlpm.h, _xlpm.getVal("h"), _xlpm.m, _xlpm.getVal("m"), _xlpm.seconds, _xlpm.w*144000 + _xlpm.d*28800 + _xlpm.h*3600 + _xlpm.m*60, IF(_xlpm.seconds=0, "", _xlpm.seconds*60) ) )} -> 3456000 | AI11: {=IFERROR( _xlfn.IFS( JiraDataset[[#This Row],[IssueType]] = cfg_type_comment,"SKIP", JiraDataset[[#This Row],[IssueType]] = cfg_type_skip,"SKIP", JiraDataset[[#This Row],[IssueType]] = cfg_type_note,"SKIP" ), cfg_type_workitem )} -> WorkItem
A12: Highest | B12: bug | C12: Session Expiry Bug | E12: Sessions not invalidated on logout | F12: JITTP Version 1 | G12: Bob B | H12: Backend | J12: 4h | K12: 10 | L12: 7 | N12: =IF(JiraDataset[[#This Row],[IssueType]]="Epic",JiraDataset[[#This Row],[Summary]],"") | AC12: =IF(JiraDataset[[#This Row],[RowType]]=cfg_type_skip,"",IFERROR(VLOOKUP(JiraDataset[[#This Row],[Sprint Name]], 'Config - Mappings'!$G$4:$H$8, 2, FALSE), "")) | AD12: =IF(JiraDataset[[#This Row],[RowType]]=cfg_type_skip,"",_xlfn.XLOOKUP("Creation Marker", CfgMisc[Name], CfgMisc[Value],"",1)) -> imported | AE12: =IF(JiraDataset[[#This Row],[RowType]]=cfg_type_skip,"",_xlfn.XLOOKUP("Work Group", CfgMisc[Name], CfgMisc[Value],"",1)) -> pod_test | AF12: =IF(JiraDataset[[#This Row],[RowType]]=cfg_type_skip,"",IFERROR(VLOOKUP(JiraDataset[[#This Row],[Assignee.Name]], 'Config - Mappings'!$A$4:$B$26, 2, FALSE), "")) -> 712020:09876543212345678905 | AG12: =IF(JiraDataset[[#This Row],[RowType]]=cfg_type_skip,"",_xlfn.XLOOKUP("jira.project.key", CfgBasic[Name], CfgBasic[Value])) -> JITTP2 | AH12: {=IF( JiraDataset[[#This Row],[RowType]]=cfg_type_skip, "", _xlfn.LET( _xlpm.p, _xlfn.TEXTSPLIT(JiraDataset[[#This Row],[Estimate]], " "), _xlpm.getVal, _xlfn.LAMBDA(_xlpm.u, IFERROR(VALUE(LEFT(_xlfn._xlws.FILTER(_xlpm.p, RIGHT(_xlpm.p,1)=_xlpm.u), LEN(_xlfn._xlws.FILTER(_xlpm.p, RIGHT(_xlpm.p,1)=_xlpm.u))-1)), 0)), _xlpm.w, _xlpm.getVal("w"), _xlpm.d, _xlpm.getVal("d"), _xlpm.h, _xlpm.getVal("h"), _xlpm.m, _xlpm.getVal("m"), _xlpm.seconds, _xlpm.w*144000 + _xlpm.d*28800 + _xlpm.h*3600 + _xlpm.m*60, IF(_xlpm.seconds=0, "", _xlpm.seconds*60) ) )} -> 864000 | AI12: {=IFERROR( _xlfn.IFS( JiraDataset[[#This Row],[IssueType]] = cfg_type_comment,"SKIP", JiraDataset[[#This Row],[IssueType]] = cfg_type_skip,"SKIP", JiraDataset[[#This Row],[IssueType]] = cfg_type_note,"SKIP" ), cfg_type_workitem )} -> WorkItem
A13: Low | B13: sub-task | C13: Add Tests for Reset Flow | E13: Write unit tests for reset controller | F13: JITTP Version 1 | G13: joe.grunt | H13: Testing | J13: 6h | K13: 11 | L13: 9 | N13: =IF(JiraDataset[[#This Row],[IssueType]]="Epic",JiraDataset[[#This Row],[Summary]],"") | AC13: =IF(JiraDataset[[#This Row],[RowType]]=cfg_type_skip,"",IFERROR(VLOOKUP(JiraDataset[[#This Row],[Sprint Name]], 'Config - Mappings'!$G$4:$H$8, 2, FALSE), "")) | AD13: =IF(JiraDataset[[#This Row],[RowType]]=cfg_type_skip,"",_xlfn.XLOOKUP("Creation Marker", CfgMisc[Name], CfgMisc[Value],"",1)) -> imported | AE13: =IF(JiraDataset[[#This Row],[RowType]]=cfg_type_skip,"",_xlfn.XLOOKUP("Work Group", CfgMisc[Name], CfgMisc[Value],"",1)) -> pod_test | AF13: =IF(JiraDataset[[#This Row],[RowType]]=cfg_type_skip,"",IFERROR(VLOOKUP(JiraDataset[[#This Row],[Assignee.Name]], 'Config - Mappings'!$A$4:$B$26, 2, FALSE), "")) -> 712020:09876543212345678901 | AG13: =IF(JiraDataset[[#This Row],[RowType]]=cfg_type_skip,"",_xlfn.XLOOKUP("jira.project.key", CfgBasic[Name], CfgBasic[Value])) -> JITTP2 | AH13: {=IF( JiraDataset[[#This Row],[RowType]]=cfg_type_skip, "", _xlfn.LET( _xlpm.p, _xlfn.TEXTSPLIT(JiraDataset[[#This Row],[Estimate]], " "), _xlpm.getVal, _xlfn.LAMBDA(_xlpm.u, IFERROR(VALUE(LEFT(_xlfn._xlws.FILTER(_xlpm.p, RIGHT(_xlpm.p,1)=_xlpm.u), LEN(_xlfn._xlws.FILTER(_xlpm.p, RIGHT(_xlpm.p,1)=_xlpm.u))-1)), 0)), _xlpm.w, _xlpm.getVal("w"), _xlpm.d, _xlpm.getVal("d"), _xlpm.h, _xlpm.getVal("h"), _xlpm.m, _xlpm.getVal("m"), _xlpm.seconds, _xlpm.w*144000 + _xlpm.d*28800 + _xlpm.h*3600 + _xlpm.m*60, IF(_xlpm.seconds=0, "", _xlpm.seconds*60) ) )} -> 1296000 | AI13: {=IFERROR( _xlfn.IFS( JiraDataset[[#This Row],[IssueType]] = cfg_type_comment,"SKIP", JiraDataset[[#This Row],[IssueType]] = cfg_type_skip,"SKIP", JiraDataset[[#This Row],[IssueType]] = cfg_type_note,"SKIP" ), cfg_type_workitem )} -> WorkItem
A14: High | B14: epic | C14: Payments & Billing | E14: Stripe integration and invoicing | F14: JITTP Version 1 | G14: john.doe | H14: Payments | J14: 1w | K14: 12 | L14: 1 | N14: =IF(JiraDataset[[#This Row],[IssueType]]="Epic",JiraDataset[[#This Row],[Summary]],"") -> Payments & Billing | AC14: =IF(JiraDataset[[#This Row],[RowType]]=cfg_type_skip,"",IFERROR(VLOOKUP(JiraDataset[[#This Row],[Sprint Name]], 'Config - Mappings'!$G$4:$H$8, 2, FALSE), "")) | AD14: =IF(JiraDataset[[#This Row],[RowType]]=cfg_type_skip,"",_xlfn.XLOOKUP("Creation Marker", CfgMisc[Name], CfgMisc[Value],"",1)) -> imported | AE14: =IF(JiraDataset[[#This Row],[RowType]]=cfg_type_skip,"",_xlfn.XLOOKUP("Work Group", CfgMisc[Name], CfgMisc[Value],"",1)) -> pod_test | AF14: =IF(JiraDataset[[#This Row],[RowType]]=cfg_type_skip,"",IFERROR(VLOOKUP(JiraDataset[[#This Row],[Assignee.Name]], 'Config - Mappings'!$A$4:$B$26, 2, FALSE), "")) -> 712020:09876543212345678902 | AG14: =IF(JiraDataset[[#This Row],[RowType]]=cfg_type_skip,"",_xlfn.XLOOKUP("jira.project.key", CfgBasic[Name], CfgBasic[Value])) -> JITTP2 | AH14: {=IF( JiraDataset[[#This Row],[RowType]]=cfg_type_skip, "", _xlfn.LET( _xlpm.p, _xlfn.TEXTSPLIT(JiraDataset[[#This Row],[Estimate]], " "), _xlpm.getVal, _xlfn.LAMBDA(_xlpm.u, IFERROR(VALUE(LEFT(_xlfn._xlws.FILTER(_xlpm.p, RIGHT(_xlpm.p,1)=_xlpm.u), LEN(_xlfn._xlws.FILTER(_xlpm.p, RIGHT(_xlpm.p,1)=_xlpm.u))-1)), 0)), _xlpm.w, _xlpm.getVal("w"), _xlpm.d, _xlpm.getVal("d"), _xlpm.h, _xlpm.getVal("h"), _xlpm.m, _xlpm.getVal("m"), _xlpm.seconds, _xlpm.w*144000 + _xlpm.d*28800 + _xlpm.h*3600 + _xlpm.m*60, IF(_xlpm.seconds=0, "", _xlpm.seconds*60) ) )} -> 8640000 | AI14: {=IFERROR( _xlfn.IFS( JiraDataset[[#This Row],[IssueType]] = cfg_type_comment,"SKIP", JiraDataset[[#This Row],[IssueType]] = cfg_type_skip,"SKIP", JiraDataset[[#This Row],[IssueType]] = cfg_type_note,"SKIP" ), cfg_type_workitem )} -> WorkItem
A15: Medium | B15: story | C15: Checkout API | E15: Implement server-side checkout | F15: JITTP Version 1 | G15: jane.smith | H15: Backend | J15: 3d | K15: 13 | L15: 12 | N15: =IF(JiraDataset[[#This Row],[IssueType]]="Epic",JiraDataset[[#This Row],[Summary]],"") | AC15: =IF(JiraDataset[[#This Row],[RowType]]=cfg_type_skip,"",IFERROR(VLOOKUP(JiraDataset[[#This Row],[Sprint Name]], 'Config - Mappings'!$G$4:$H$8, 2, FALSE), "")) | AD15: =IF(JiraDataset[[#This Row],[RowType]]=cfg_type_skip,"",_xlfn.XLOOKUP("Creation Marker", CfgMisc[Name], CfgMisc[Value],"",1)) -> imported | AE15: =IF(JiraDataset[[#This Row],[RowType]]=cfg_type_skip,"",_xlfn.XLOOKUP("Work Group", CfgMisc[Name], CfgMisc[Value],"",1)) -> pod_test | AF15: =IF(JiraDataset[[#This Row],[RowType]]=cfg_type_skip,"",IFERROR(VLOOKUP(JiraDataset[[#This Row],[Assignee.Name]], 'Config - Mappings'!$A$4:$B$26, 2, FALSE), "")) -> 712020:09876543212345678903 | AG15: =IF(JiraDataset[[#This Row],[RowType]]=cfg_type_skip,"",_xlfn.XLOOKUP("jira.project.key", CfgBasic[Name], CfgBasic[Value])) -> JITTP2 | AH15: {=IF( JiraDataset[[#This Row],[RowType]]=cfg_type_skip, "", _xlfn.LET( _xlpm.p, _xlfn.TEXTSPLIT(JiraDataset[[#This Row],[Estimate]], " "), _xlpm.getVal, _xlfn.LAMBDA(_xlpm.u, IFERROR(VALUE(LEFT(_xlfn._xlws.FILTER(_xlpm.p, RIGHT(_xlpm.p,1)=_xlpm.u), LEN(_xlfn._xlws.FILTER(_xlpm.p, RIGHT(_xlpm.p,1)=_xlpm.u))-1)), 0)), _xlpm.w, _xlpm.getVal("w"), _xlpm.d, _xlpm.getVal("d"), _xlpm.h, _xlpm.getVal("h"), _xlpm.m, _xlpm.getVal("m"), _xlpm.seconds, _xlpm.w*144000 + _xlpm.d*28800 + _xlpm.h*3600 + _xlpm.m*60, IF(_xlpm.seconds=0, "", _xlpm.seconds*60) ) )} -> 5184000 | AI15: {=IFERROR( _xlfn.IFS( JiraDataset[[#This Row],[IssueType]] = cfg_type_comment,"SKIP", JiraDataset[[#This Row],[IssueType]] = cfg_type_skip,"SKIP", JiraDataset[[#This Row],[IssueType]] = cfg_type_note,"SKIP" ), cfg_type_workitem )} -> WorkItem
... A18: Medium | B18: sub-task | C18: Edge-Case Tests | E18: Add e2e tests for failed payments | F18: JITTP Version 1 | G18: joe.grunt | H18: Testing | J18: 1d | K18: 16 | L18: 13 | N18: =IF(JiraDataset[[#This Row],[IssueType]]="Epic",JiraDataset[[#This Row],[Summary]],"") | AC18: =IF(JiraDataset[[#This Row],[RowType]]=cfg_type_skip,"",IFERROR(VLOOKUP(JiraDataset[[#This Row],[Sprint Name]], 'Config - Mappings'!$G$4:$H$8, 2, FALSE), "")) | AD18: =IF(JiraDataset[[#This Row],[RowType]]=cfg_type_skip,"",_xlfn.XLOOKUP("Creation Marker", CfgMisc[Name], CfgMisc[Value],"",1)) -> imported | AE18: =IF(JiraDataset[[#This Row],[RowType]]=cfg_type_skip,"",_xlfn.XLOOKUP("Work Group", CfgMisc[Name], CfgMisc[Value],"",1)) -> pod_test | AF18: =IF(JiraDataset[[#This Row],[RowType]]=cfg_type_skip,"",IFERROR(VLOOKUP(JiraDataset[[#This Row],[Assignee.Name]], 'Config - Mappings'!$A$4:$B$26, 2, FALSE), "")) -> 712020:09876543212345678901 | AG18: =IF(JiraDataset[[#This Row],[RowType]]=cfg_type_skip,"",_xlfn.XLOOKUP("jira.project.key", CfgBasic[Name], CfgBasic[Value])) -> JITTP2 | AH18: {=IF( JiraDataset[[#This Row],[RowType]]=cfg_type_skip, "", _xlfn.LET( _xlpm.p, _xlfn.TEXTSPLIT(JiraDataset[[#This Row],[Estimate]], " "), _xlpm.getVal, _xlfn.LAMBDA(_xlpm.u, IFERROR(VALUE(LEFT(_xlfn._xlws.FILTER(_xlpm.p, RIGHT(_xlpm.p,1)=_xlpm.u), LEN(_xlfn._xlws.FILTER(_xlpm.p, RIGHT(_xlpm.p,1)=_xlpm.u))-1)), 0)), _xlpm.w, _xlpm.getVal("w"), _xlpm.d, _xlpm.getVal("d"), _xlpm.h, _xlpm.getVal("h"), _xlpm.m, _xlpm.getVal("m"), _xlpm.seconds, _xlpm.w*144000 + _xlpm.d*28800 + _xlpm.h*3600 + _xlpm.m*60, IF(_xlpm.seconds=0, "", _xlpm.seconds*60) ) )} -> 1728000 | AI18: {=IFERROR( _xlfn.IFS( JiraDataset[[#This Row],[IssueType]] = cfg_type_comment,"SKIP", JiraDataset[[#This Row],[IssueType]] = cfg_type_skip,"SKIP", JiraDataset[[#This Row],[IssueType]] = cfg_type_note,"SKIP" ), cfg_type_workitem )} -> WorkItem
A19: High | B19: initiative | C19: Mobile & Growth | E19: Mobile-first initiative to grow MAU | F19: JITTP Version 1 | G19: john.doe | H19: Strategy | J19: 2w | K19: 17 | N19: =IF(JiraDataset[[#This Row],[IssueType]]="Epic",JiraDataset[[#This Row],[Summary]],"") | AC19: =IF(JiraDataset[[#This Row],[RowType]]=cfg_type_skip,"",IFERROR(VLOOKUP(JiraDataset[[#This Row],[Sprint Name]], 'Config - Mappings'!$G$4:$H$8, 2, FALSE), "")) | AD19: =IF(JiraDataset[[#This Row],[RowType]]=cfg_type_skip,"",_xlfn.XLOOKUP("Creation Marker", CfgMisc[Name], CfgMisc[Value],"",1)) -> imported | AE19: =IF(JiraDataset[[#This Row],[RowType]]=cfg_type_skip,"",_xlfn.XLOOKUP("Work Group", CfgMisc[Name], CfgMisc[Value],"",1)) -> pod_test | AF19: =IF(JiraDataset[[#This Row],[RowType]]=cfg_type_skip,"",IFERROR(VLOOKUP(JiraDataset[[#This Row],[Assignee.Name]], 'Config - Mappings'!$A$4:$B$26, 2, FALSE), "")) -> 712020:09876543212345678902 | AG19: =IF(JiraDataset[[#This Row],[RowType]]=cfg_type_skip,"",_xlfn.XLOOKUP("jira.project.key", CfgBasic[Name], CfgBasic[Value])) -> JITTP2 | AH19: {=IF( JiraDataset[[#This Row],[RowType]]=cfg_type_skip, "", _xlfn.LET( _xlpm.p, _xlfn.TEXTSPLIT(JiraDataset[[#This Row],[Estimate]], " "), _xlpm.getVal, _xlfn.LAMBDA(_xlpm.u, IFERROR(VALUE(LEFT(_xlfn._xlws.FILTER(_xlpm.p, RIGHT(_xlpm.p,1)=_xlpm.u), LEN(_xlfn._xlws.FILTER(_xlpm.p, RIGHT(_xlpm.p,1)=_xlpm.u))-1)), 0)), _xlpm.w, _xlpm.getVal("w"), _xlpm.d, _xlpm.getVal("d"), _xlpm.h, _xlpm.getVal("h"), _xlpm.m, _xlpm.getVal("m"), _xlpm.seconds, _xlpm.w*144000 + _xlpm.d*28800 + _xlpm.h*3600 + _xlpm.m*60, IF(_xlpm.seconds=0, "", _xlpm.seconds*60) ) )} -> 17280000 | AI19: {=IFERROR( _xlfn.IFS( JiraDataset[[#This Row],[IssueType]] = cfg_type_comment,"SKIP", JiraDataset[[#This Row],[IssueType]] = cfg_type_skip,"SKIP", JiraDataset[[#This Row],[IssueType]] = cfg_type_note,"SKIP" ), cfg_type_workitem )} -> WorkItem
A20: Medium | B20: epic | C20: Mobile App UX | E20: Refine navigation and gestures on mobile | F20: JITTP Version 1 | G20: jane.smith | H20: Frontend | J20: 1w | K20: 18 | L20: 17 | N20: =IF(JiraDataset[[#This Row],[IssueType]]="Epic",JiraDataset[[#This Row],[Summary]],"") -> Mobile App UX | AC20: =IF(JiraDataset[[#This Row],[RowType]]=cfg_type_skip,"",IFERROR(VLOOKUP(JiraDataset[[#This Row],[Sprint Name]], 'Config - Mappings'!$G$4:$H$8, 2, FALSE), "")) | AD20: =IF(JiraDataset[[#This Row],[RowType]]=cfg_type_skip,"",_xlfn.XLOOKUP("Creation Marker", CfgMisc[Name], CfgMisc[Value],"",1)) -> imported | AE20: =IF(JiraDataset[[#This Row],[RowType]]=cfg_type_skip,"",_xlfn.XLOOKUP("Work Group", CfgMisc[Name], CfgMisc[Value],"",1)) -> pod_test | AF20: =IF(JiraDataset[[#This Row],[RowType]]=cfg_type_skip,"",IFERROR(VLOOKUP(JiraDataset[[#This Row],[Assignee.Name]], 'Config - Mappings'!$A$4:$B$26, 2, FALSE), "")) -> 712020:09876543212345678903 | AG20: =IF(JiraDataset[[#This Row],[RowType]]=cfg_type_skip,"",_xlfn.XLOOKUP("jira.project.key", CfgBasic[Name], CfgBasic[Value])) -> JITTP2 | AH20: {=IF( JiraDataset[[#This Row],[RowType]]=cfg_type_skip, "", _xlfn.LET( _xlpm.p, _xlfn.TEXTSPLIT(JiraDataset[[#This Row],[Estimate]], " "), _xlpm.getVal, _xlfn.LAMBDA(_xlpm.u, IFERROR(VALUE(LEFT(_xlfn._xlws.FILTER(_xlpm.p, RIGHT(_xlpm.p,1)=_xlpm.u), LEN(_xlfn._xlws.FILTER(_xlpm.p, RIGHT(_xlpm.p,1)=_xlpm.u))-1)), 0)), _xlpm.w, _xlpm.getVal("w"), _xlpm.d, _xlpm.getVal("d"), _xlpm.h, _xlpm.getVal("h"), _xlpm.m, _xlpm.getVal("m"), _xlpm.seconds, _xlpm.w*144000 + _xlpm.d*28800 + _xlpm.h*3600 + _xlpm.m*60, IF(_xlpm.seconds=0, "", _xlpm.seconds*60) ) )} -> 8640000 | AI20: {=IFERROR( _xlfn.IFS( JiraDataset[[#This Row],[IssueType]] = cfg_type_comment,"SKIP", JiraDataset[[#This Row],[IssueType]] = cfg_type_skip,"SKIP", JiraDataset[[#This Row],[IssueType]] = cfg_type_note,"SKIP" ), cfg_type_workitem )} -> WorkItem
A21: Highest | B21: story | C21: Responsive Layout | E21: Implement responsive grid and breakpoints | F21: JITTP Version 1 | G21: Alice A | H21: Frontend | J21: 3d | K21: 19 | L21: 18 | N21: =IF(JiraDataset[[#This Row],[IssueType]]="Epic",JiraDataset[[#This Row],[Summary]],"") | AC21: =IF(JiraDataset[[#This Row],[RowType]]=cfg_type_skip,"",IFERROR(VLOOKUP(JiraDataset[[#This Row],[Sprint Name]], 'Config - Mappings'!$G$4:$H$8, 2, FALSE), "")) | AD21: =IF(JiraDataset[[#This Row],[RowType]]=cfg_type_skip,"",_xlfn.XLOOKUP("Creation Marker", CfgMisc[Name], CfgMisc[Value],"",1)) -> imported | AE21: =IF(JiraDataset[[#This Row],[RowType]]=cfg_type_skip,"",_xlfn.XLOOKUP("Work Group", CfgMisc[Name], CfgMisc[Value],"",1)) -> pod_test | AF21: =IF(JiraDataset[[#This Row],[RowType]]=cfg_type_skip,"",IFERROR(VLOOKUP(JiraDataset[[#This Row],[Assignee.Name]], 'Config - Mappings'!$A$4:$B$26, 2, FALSE), "")) -> 712020:09876543212345678904 | AG21: =IF(JiraDataset[[#This Row],[RowType]]=cfg_type_skip,"",_xlfn.XLOOKUP("jira.project.key", CfgBasic[Name], CfgBasic[Value])) -> JITTP2 | AH21: {=IF( JiraDataset[[#This Row],[RowType]]=cfg_type_skip, "", _xlfn.LET( _xlpm.p, _xlfn.TEXTSPLIT(JiraDataset[[#This Row],[Estimate]], " "), _xlpm.getVal, _xlfn.LAMBDA(_xlpm.u, IFERROR(VALUE(LEFT(_xlfn._xlws.FILTER(_xlpm.p, RIGHT(_xlpm.p,1)=_xlpm.u), LEN(_xlfn._xlws.FILTER(_xlpm.p, RIGHT(_xlpm.p,1)=_xlpm.u))-1)), 0)), _xlpm.w, _xlpm.getVal("w"), _xlpm.d, _xlpm.getVal("d"), _xlpm.h, _xlpm.getVal("h"), _xlpm.m, _xlpm.getVal("m"), _xlpm.seconds, _xlpm.w*144000 + _xlpm.d*28800 + _xlpm.h*3600 + _xlpm.m*60, IF(_xlpm.seconds=0, "", _xlpm.seconds*60) ) )} -> 5184000 | AI21: {=IFERROR( _xlfn.IFS( JiraDataset[[#This Row],[IssueType]] = cfg_type_comment,"SKIP", JiraDataset[[#This Row],[IssueType]] = cfg_type_skip,"SKIP", JiraDataset[[#This Row],[IssueType]] = cfg_type_note,"SKIP" ), cfg_type_workitem )} -> WorkItem
A22: High | B22: task | C22: Touch Gestures | E22: Add swipe/long-press interactions | F22: JITTP Version 1 | G22: Bob B | H22: Frontend | J22: 2d | K22: 20 | L22: 18 | N22: =IF(JiraDataset[[#This Row],[IssueType]]="Epic",JiraDataset[[#This Row],[Summary]],"") | AC22: =IF(JiraDataset[[#This Row],[RowType]]=cfg_type_skip,"",IFERROR(VLOOKUP(JiraDataset[[#This Row],[Sprint Name]], 'Config - Mappings'!$G$4:$H$8, 2, FALSE), "")) | AD22: =IF(JiraDataset[[#This Row],[RowType]]=cfg_type_skip,"",_xlfn.XLOOKUP("Creation Marker", CfgMisc[Name], CfgMisc[Value],"",1)) -> imported | AE22: =IF(JiraDataset[[#This Row],[RowType]]=cfg_type_skip,"",_xlfn.XLOOKUP("Work Group", CfgMisc[Name], CfgMisc[Value],"",1)) -> pod_test | AF22: =IF(JiraDataset[[#This Row],[RowType]]=cfg_type_skip,"",IFERROR(VLOOKUP(JiraDataset[[#This Row],[Assignee.Name]], 'Config - Mappings'!$A$4:$B$26, 2, FALSE), "")) -> 712020:09876543212345678905 | AG22: =IF(JiraDataset[[#This Row],[RowType]]=cfg_type_skip,"",_xlfn.XLOOKUP("jira.project.key", CfgBasic[Name], CfgBasic[Value])) -> JITTP2 | AH22: {=IF( JiraDataset[[#This Row],[RowType]]=cfg_type_skip, "", _xlfn.LET( _xlpm.p, _xlfn.TEXTSPLIT(JiraDataset[[#This Row],[Estimate]], " "), _xlpm.getVal, _xlfn.LAMBDA(_xlpm.u, IFERROR(VALUE(LEFT(_xlfn._xlws.FILTER(_xlpm.p, RIGHT(_xlpm.p,1)=_xlpm.u), LEN(_xlfn._xlws.FILTER(_xlpm.p, RIGHT(_xlpm.p,1)=_xlpm.u))-1)), 0)), _xlpm.w, _xlpm.getVal("w"), _xlpm.d, _xlpm.getVal("d"), _xlpm.h, _xlpm.getVal("h"), _xlpm.m, _xlpm.getVal("m"), _xlpm.seconds, _xlpm.w*144000 + _xlpm.d*28800 + _xlpm.h*3600 + _xlpm.m*60, IF(_xlpm.seconds=0, "", _xlpm.seconds*60) ) )} -> 3456000 | AI22: {=IFERROR( _xlfn.IFS( JiraDataset[[#This Row],[IssueType]] = cfg_type_comment,"SKIP", JiraDataset[[#This Row],[IssueType]] = cfg_type_skip,"SKIP", JiraDataset[[#This Row],[IssueType]] = cfg_type_note,"SKIP" ), cfg_type_workitem )} -> WorkItem
A23: Low | B23: bug | C23: Gesture Misfire Bug | E23: Swipe back triggers on tap | F23: JITTP Version 1 | G23: joe.grunt | H23: Frontend | J23: 6h | K23: 21 | L23: 18 | N23: =IF(JiraDataset[[#This Row],[IssueType]]="Epic",JiraDataset[[#This Row],[Summary]],"") | AC23: =IF(JiraDataset[[#This Row],[RowType]]=cfg_type_skip,"",IFERROR(VLOOKUP(JiraDataset[[#This Row],[Sprint Name]], 'Config - Mappings'!$G$4:$H$8, 2, FALSE), "")) | AD23: =IF(JiraDataset[[#This Row],[RowType]]=cfg_type_skip,"",_xlfn.XLOOKUP("Creation Marker", CfgMisc[Name], CfgMisc[Value],"",1)) -> imported | AE23: =IF(JiraDataset[[#This Row],[RowType]]=cfg_type_skip,"",_xlfn.XLOOKUP("Work Group", CfgMisc[Name], CfgMisc[Value],"",1)) -> pod_test | AF23: =IF(JiraDataset[[#This Row],[RowType]]=cfg_type_skip,"",IFERROR(VLOOKUP(JiraDataset[[#This Row],[Assignee.Name]], 'Config - Mappings'!$A$4:$B$26, 2, FALSE), "")) -> 712020:09876543212345678901 | AG23: =IF(JiraDataset[[#This Row],[RowType]]=cfg_type_skip,"",_xlfn.XLOOKUP("jira.project.key", CfgBasic[Name], CfgBasic[Value])) -> JITTP2 | AH23: {=IF( JiraDataset[[#This Row],[RowType]]=cfg_type_skip, "", _xlfn.LET( _xlpm.p, _xlfn.TEXTSPLIT(JiraDataset[[#This Row],[Estimate]], " "), _xlpm.getVal, _xlfn.LAMBDA(_xlpm.u, IFERROR(VALUE(LEFT(_xlfn._xlws.FILTER(_xlpm.p, RIGHT(_xlpm.p,1)=_xlpm.u), LEN(_xlfn._xlws.FILTER(_xlpm.p, RIGHT(_xlpm.p,1)=_xlpm.u))-1)), 0)), _xlpm.w, _xlpm.getVal("w"), _xlpm.d, _xlpm.getVal("d"), _xlpm.h, _xlpm.getVal("h"), _xlpm.m, _xlpm.getVal("m"), _xlpm.seconds, _xlpm.w*144000 + _xlpm.d*28800 + _xlpm.h*3600 + _xlpm.m*60, IF(_xlpm.seconds=0, "", _xlpm.seconds*60) ) )} -> 1296000 | AI23: {=IFERROR( _xlfn.IFS( JiraDataset[[#This Row],[IssueType]] = cfg_type_comment,"SKIP", JiraDataset[[#This Row],[IssueType]] = cfg_type_skip,"SKIP", JiraDataset[[#This Row],[IssueType]] = cfg_type_note,"SKIP" ), cfg_type_workitem )} -> WorkItem
A24: Lowest | B24: sub-task | C24: Gesture Regression Tests | E24: Automate gesture tests on devices | F24: JITTP Version 1 | G24: john.doe | H24: Testing | J24: 1d | K24: 22 | L24: 21 | N24: =IF(JiraDataset[[#This Row],[IssueType]]="Epic",JiraDataset[[#This Row],[Summary]],"") | AC24: =IF(JiraDataset[[#This Row],[RowType]]=cfg_type_skip,"",IFERROR(VLOOKUP(JiraDataset[[#This Row],[Sprint Name]], 'Config - Mappings'!$G$4:$H$8, 2, FALSE), "")) | AD24: =IF(JiraDataset[[#This Row],[RowType]]=cfg_type_skip,"",_xlfn.XLOOKUP("Creation Marker", CfgMisc[Name], CfgMisc[Value],"",1)) -> imported | AE24: =IF(JiraDataset[[#This Row],[RowType]]=cfg_type_skip,"",_xlfn.XLOOKUP("Work Group", CfgMisc[Name], CfgMisc[Value],"",1)) -> pod_test | AF24: =IF(JiraDataset[[#This Row],[RowType]]=cfg_type_skip,"",IFERROR(VLOOKUP(JiraDataset[[#This Row],[Assignee.Name]], 'Config - Mappings'!$A$4:$B$26, 2, FALSE), "")) -> 712020:09876543212345678902 | AG24: =IF(JiraDataset[[#This Row],[RowType]]=cfg_type_skip,"",_xlfn.XLOOKUP("jira.project.key", CfgBasic[Name], CfgBasic[Value])) -> JITTP2 | AH24: {=IF( JiraDataset[[#This Row],[RowType]]=cfg_type_skip, "", _xlfn.LET( _xlpm.p, _xlfn.TEXTSPLIT(JiraDataset[[#This Row],[Estimate]], " "), _xlpm.getVal, _xlfn.LAMBDA(_xlpm.u, IFERROR(VALUE(LEFT(_xlfn._xlws.FILTER(_xlpm.p, RIGHT(_xlpm.p,1)=_xlpm.u), LEN(_xlfn._xlws.FILTER(_xlpm.p, RIGHT(_xlpm.p,1)=_xlpm.u))-1)), 0)), _xlpm.w, _xlpm.getVal("w"), _xlpm.d, _xlpm.getVal("d"), _xlpm.h, _xlpm.getVal("h"), _xlpm.m, _xlpm.getVal("m"), _xlpm.seconds, _xlpm.w*144000 + _xlpm.d*28800 + _xlpm.h*3600 + _xlpm.m*60, IF(_xlpm.seconds=0, "", _xlpm.seconds*60) ) )} -> 1728000 | AI24: {=IFERROR( _xlfn.IFS( JiraDataset[[#This Row],[IssueType]] = cfg_type_comment,"SKIP", JiraDataset[[#This Row],[IssueType]] = cfg_type_skip,"SKIP", JiraDataset[[#This Row],[IssueType]] = cfg_type_note,"SKIP" ), cfg_type_workitem )} -> WorkItem
A25: Triage | B25: epic | C25: Admin & Permissions | E25: Granular roles and permissions | F25: JITTP Version 1 | G25: jane.smith | H25: Security | J25: 1w | K25: 23 | L25: 17 | N25: =IF(JiraDataset[[#This Row],[IssueType]]="Epic",JiraDataset[[#This Row],[Summary]],"") -> Admin & Permissions | AC25: =IF(JiraDataset[[#This Row],[RowType]]=cfg_type_skip,"",IFERROR(VLOOKUP(JiraDataset[[#This Row],[Sprint Name]], 'Config - Mappings'!$G$4:$H$8, 2, FALSE), "")) | AD25: =IF(JiraDataset[[#This Row],[RowType]]=cfg_type_skip,"",_xlfn.XLOOKUP("Creation Marker", CfgMisc[Name], CfgMisc[Value],"",1)) -> imported | AE25: =IF(JiraDataset[[#This Row],[RowType]]=cfg_type_skip,"",_xlfn.XLOOKUP("Work Group", CfgMisc[Name], CfgMisc[Value],"",1)) -> pod_test | AF25: =IF(JiraDataset[[#This Row],[RowType]]=cfg_type_skip,"",IFERROR(VLOOKUP(JiraDataset[[#This Row],[Assignee.Name]], 'Config - Mappings'!$A$4:$B$26, 2, FALSE), "")) -> 712020:09876543212345678903 | AG25: =IF(JiraDataset[[#This Row],[RowType]]=cfg_type_skip,"",_xlfn.XLOOKUP("jira.project.key", CfgBasic[Name], CfgBasic[Value])) -> JITTP2 | AH25: {=IF( JiraDataset[[#This Row],[RowType]]=cfg_type_skip, "", _xlfn.LET( _xlpm.p, _xlfn.TEXTSPLIT(JiraDataset[[#This Row],[Estimate]], " "), _xlpm.getVal, _xlfn.LAMBDA(_xlpm.u, IFERROR(VALUE(LEFT(_xlfn._xlws.FILTER(_xlpm.p, RIGHT(_xlpm.p,1)=_xlpm.u), LEN(_xlfn._xlws.FILTER(_xlpm.p, RIGHT(_xlpm.p,1)=_xlpm.u))-1)), 0)), _xlpm.w, _xlpm.getVal("w"), _xlpm.d, _xlpm.getVal("d"), _xlpm.h, _xlpm.getVal("h"), _xlpm.m, _xlpm.getVal("m"), _xlpm.seconds, _xlpm.w*144000 + _xlpm.d*28800 + _xlpm.h*3600 + _xlpm.m*60, IF(_xlpm.seconds=0, "", _xlpm.seconds*60) ) )} -> 8640000 | AI25: {=IFERROR( _xlfn.IFS( JiraDataset[[#This Row],[IssueType]] = cfg_type_comment,"SKIP", JiraDataset[[#This Row],[IssueType]] = cfg_type_skip,"SKIP", JiraDataset[[#This Row],[IssueType]] = cfg_type_note,"SKIP" ), cfg_type_workitem )} -> WorkItem
A26: High | B26: story | C26: Role Model Design | E26: Define roles/claims and inheritance | F26: JITTP Version 1 | G26: Alice A | H26: Backend | J26: 2d | K26: 24 | L26: 23 | N26: =IF(JiraDataset[[#This Row],[IssueType]]="Epic",JiraDataset[[#This Row],[Summary]],"") | AC26: =IF(JiraDataset[[#This Row],[RowType]]=cfg_type_skip,"",IFERROR(VLOOKUP(JiraDataset[[#This Row],[Sprint Name]], 'Config - Mappings'!$G$4:$H$8, 2, FALSE), "")) | AD26: =IF(JiraDataset[[#This Row],[RowType]]=cfg_type_skip,"",_xlfn.XLOOKUP("Creation Marker", CfgMisc[Name], CfgMisc[Value],"",1)) -> imported | AE26: =IF(JiraDataset[[#This Row],[RowType]]=cfg_type_skip,"",_xlfn.XLOOKUP("Work Group", CfgMisc[Name], CfgMisc[Value],"",1)) -> pod_test | AF26: =IF(JiraDataset[[#This Row],[RowType]]=cfg_type_skip,"",IFERROR(VLOOKUP(JiraDataset[[#This Row],[Assignee.Name]], 'Config - Mappings'!$A$4:$B$26, 2, FALSE), "")) -> 712020:09876543212345678904 | AG26: =IF(JiraDataset[[#This Row],[RowType]]=cfg_type_skip,"",_xlfn.XLOOKUP("jira.project.key", CfgBasic[Name], CfgBasic[Value])) -> JITTP2 | AH26: {=IF( JiraDataset[[#This Row],[RowType]]=cfg_type_skip, "", _xlfn.LET( _xlpm.p, _xlfn.TEXTSPLIT(JiraDataset[[#This Row],[Estimate]], " "), _xlpm.getVal, _xlfn.LAMBDA(_xlpm.u, IFERROR(VALUE(LEFT(_xlfn._xlws.FILTER(_xlpm.p, RIGHT(_xlpm.p,1)=_xlpm.u), LEN(_xlfn._xlws.FILTER(_xlpm.p, RIGHT(_xlpm.p,1)=_xlpm.u))-1)), 0)), _xlpm.w, _xlpm.getVal("w"), _xlpm.d, _xlpm.getVal("d"), _xlpm.h, _xlpm.getVal("h"), _xlpm.m, _xlpm.getVal("m"), _xlpm.seconds, _xlpm.w*144000 + _xlpm.d*28800 + _xlpm.h*3600 + _xlpm.m*60, IF(_xlpm.seconds=0, "", _xlpm.seconds*60) ) )} -> 3456000 | AI26: {=IFERROR( _xlfn.IFS( JiraDataset[[#This Row],[IssueType]] = cfg_type_comment,"SKIP", JiraDataset[[#This Row],[IssueType]] = cfg_type_skip,"SKIP", JiraDataset[[#This Row],[IssueType]] = cfg_type_note,"SKIP" ), cfg_type_workitem )} -> WorkItem
A27: Medium | B27: task | C27: Permission Editor UI | E27: Create admin UI to manage permissions | F27: JITTP Version 1 | G27: Bob B | H27: Frontend | J27: 3d | K27: 25 | L27: 23 | N27: =IF(JiraDataset[[#This Row],[IssueType]]="Epic",JiraDataset[[#This Row],[Summary]],"") | AC27: =IF(JiraDataset[[#This Row],[RowType]]=cfg_type_skip,"",IFERROR(VLOOKUP(JiraDataset[[#This Row],[Sprint Name]], 'Config - Mappings'!$G$4:$H$8, 2, FALSE), "")) | AD27: =IF(JiraDataset[[#This Row],[RowType]]=cfg_type_skip,"",_xlfn.XLOOKUP("Creation Marker", CfgMisc[Name], CfgMisc[Value],"",1)) -> imported | AE27: =IF(JiraDataset[[#This Row],[RowType]]=cfg_type_skip,"",_xlfn.XLOOKUP("Work Group", CfgMisc[Name], CfgMisc[Value],"",1)) -> pod_test | AF27: =IF(JiraDataset[[#This Row],[RowType]]=cfg_type_skip,"",IFERROR(VLOOKUP(JiraDataset[[#This Row],[Assignee.Name]], 'Config - Mappings'!$A$4:$B$26, 2, FALSE), "")) -> 712020:09876543212345678905 | AG27: =IF(JiraDataset[[#This Row],[RowType]]=cfg_type_skip,"",_xlfn.XLOOKUP("jira.project.key", CfgBasic[Name], CfgBasic[Value])) -> JITTP2 | AH27: {=IF( JiraDataset[[#This Row],[RowType]]=cfg_type_skip, "", _xlfn.LET( _xlpm.p, _xlfn.TEXTSPLIT(JiraDataset[[#This Row],[Estimate]], " "), _xlpm.getVal, _xlfn.LAMBDA(_xlpm.u, IFERROR(VALUE(LEFT(_xlfn._xlws.FILTER(_xlpm.p, RIGHT(_xlpm.p,1)=_xlpm.u), LEN(_xlfn._xlws.FILTER(_xlpm.p, RIGHT(_xlpm.p,1)=_xlpm.u))-1)), 0)), _xlpm.w, _xlpm.getVal("w"), _xlpm.d, _xlpm.getVal("d"), _xlpm.h, _xlpm.getVal("h"), _xlpm.m, _xlpm.getVal("m"), _xlpm.seconds, _xlpm.w*144000 + _xlpm.d*28800 + _xlpm.h*3600 + _xlpm.m*60, IF(_xlpm.seconds=0, "", _xlpm.seconds*60) ) )} -> 5184000 | AI27: {=IFERROR( _xlfn.IFS( JiraDataset[[#This Row],[IssueType]] = cfg_type_comment,"SKIP", JiraDataset[[#This Row],[IssueType]] = cfg_type_skip,"SKIP", JiraDataset[[#This Row],[IssueType]] = cfg_type_note,"SKIP" ), cfg_type_workitem )} -> WorkItem
A28: Highest | B28: bug | C28: Access Denied Bug | E28: Authorized users blocked by guard | F28: JITTP Version 1 | G28: joe.grunt | H28: Backend | J28: 1d | K28: 26 | L28: 23 | N28: =IF(JiraDataset[[#This Row],[IssueType]]="Epic",JiraDataset[[#This Row],[Summary]],"") | AC28: =IF(JiraDataset[[#This Row],[RowType]]=cfg_type_skip,"",IFERROR(VLOOKUP(JiraDataset[[#This Row],[Sprint Name]], 'Config - Mappings'!$G$4:$H$8, 2, FALSE), "")) | AD28: =IF(JiraDataset[[#This Row],[RowType]]=cfg_type_skip,"",_xlfn.XLOOKUP("Creation Marker", CfgMisc[Name], CfgMisc[Value],"",1)) -> imported | AE28: =IF(JiraDataset[[#This Row],[RowType]]=cfg_type_skip,"",_xlfn.XLOOKUP("Work Group", CfgMisc[Name], CfgMisc[Value],"",1)) -> pod_test | AF28: =IF(JiraDataset[[#This Row],[RowType]]=cfg_type_skip,"",IFERROR(VLOOKUP(JiraDataset[[#This Row],[Assignee.Name]], 'Config - Mappings'!$A$4:$B$26, 2, FALSE), "")) -> 712020:09876543212345678901 | AG28: =IF(JiraDataset[[#This Row],[RowType]]=cfg_type_skip,"",_xlfn.XLOOKUP("jira.project.key", CfgBasic[Name], CfgBasic[Value])) -> JITTP2 | AH28: {=IF( JiraDataset[[#This Row],[RowType]]=cfg_type_skip, "", _xlfn.LET( _xlpm.p, _xlfn.TEXTSPLIT(JiraDataset[[#This Row],[Estimate]], " "), _xlpm.getVal, _xlfn.LAMBDA(_xlpm.u, IFERROR(VALUE(LEFT(_xlfn._xlws.FILTER(_xlpm.p, RIGHT(_xlpm.p,1)=_xlpm.u), LEN(_xlfn._xlws.FILTER(_xlpm.p, RIGHT(_xlpm.p,1)=_xlpm.u))-1)), 0)), _xlpm.w, _xlpm.getVal("w"), _xlpm.d, _xlpm.getVal("d"), _xlpm.h, _xlpm.getVal("h"), _xlpm.m, _xlpm.getVal("m"), _xlpm.seconds, _xlpm.w*144000 + _xlpm.d*28800 + _xlpm.h*3600 + _xlpm.m*60, IF(_xlpm.seconds=0, "", _xlpm.seconds*60) ) )} -> 1728000 | AI28: {=IFERROR( _xlfn.IFS( JiraDataset[[#This Row],[IssueType]] = cfg_type_comment,"SKIP", JiraDataset[[#This Row],[IssueType]] = cfg_type_skip,"SKIP", JiraDataset[[#This Row],[IssueType]] = cfg_type_note,"SKIP" ), cfg_type_workitem )} -> WorkItem
A29: Low | B29: sub-task | C29: Unit Tests: Guards | E29: Add unit tests for permission guards | F29: JITTP Version 1 | G29: john.doe | H29: Testing | J29: 6h | K29: 27 | L29: 24 | N29: =IF(JiraDataset[[#This Row],[IssueType]]="Epic",JiraDataset[[#This Row],[Summary]],"") | AC29: =IF(JiraDataset[[#This Row],[RowType]]=cfg_type_skip,"",IFERROR(VLOOKUP(JiraDataset[[#This Row],[Sprint Name]], 'Config - Mappings'!$G$4:$H$8, 2, FALSE), "")) | AD29: =IF(JiraDataset[[#This Row],[RowType]]=cfg_type_skip,"",_xlfn.XLOOKUP("Creation Marker", CfgMisc[Name], CfgMisc[Value],"",1)) -> imported | AE29: =IF(JiraDataset[[#This Row],[RowType]]=cfg_type_skip,"",_xlfn.XLOOKUP("Work Group", CfgMisc[Name], CfgMisc[Value],"",1)) -> pod_test | AF29: =IF(JiraDataset[[#This Row],[RowType]]=cfg_type_skip,"",IFERROR(VLOOKUP(JiraDataset[[#This Row],[Assignee.Name]], 'Config - Mappings'!$A$4:$B$26, 2, FALSE), "")) -> 712020:09876543212345678902 | AG29: =IF(JiraDataset[[#This Row],[RowType]]=cfg_type_skip,"",_xlfn.XLOOKUP("jira.project.key", CfgBasic[Name], CfgBasic[Value])) -> JITTP2 | AH29: {=IF( JiraDataset[[#This Row],[RowType]]=cfg_type_skip, "", _xlfn.LET( _xlpm.p, _xlfn.TEXTSPLIT(JiraDataset[[#This Row],[Estimate]], " "), _xlpm.getVal, _xlfn.LAMBDA(_xlpm.u, IFERROR(VALUE(LEFT(_xlfn._xlws.FILTER(_xlpm.p, RIGHT(_xlpm.p,1)=_xlpm.u), LEN(_xlfn._xlws.FILTER(_xlpm.p, RIGHT(_xlpm.p,1)=_xlpm.u))-1)), 0)), _xlpm.w, _xlpm.getVal("w"), _xlpm.d, _xlpm.getVal("d"), _xlpm.h, _xlpm.getVal("h"), _xlpm.m, _xlpm.getVal("m"), _xlpm.seconds, _xlpm.w*144000 + _xlpm.d*28800 + _xlpm.h*3600 + _xlpm.m*60, IF(_xlpm.seconds=0, "", _xlpm.seconds*60) ) )} -> 1296000 | AI29: {=IFERROR( _xlfn.IFS( JiraDataset[[#This Row],[IssueType]] = cfg_type_comment,"SKIP", JiraDataset[[#This Row],[IssueType]] = cfg_type_skip,"SKIP", JiraDataset[[#This Row],[IssueType]] = cfg_type_note,"SKIP" ), cfg_type_workitem )} -> WorkItem
A30: High | B30: epic | C30: Localization & Accessibility | E30: Internationalization and a11y | F30: JITTP Version 1 | G30: jane.smith | H30: Localization | J30: 1w | K30: 28 | L30: 17 | N30: =IF(JiraDataset[[#This Row],[IssueType]]="Epic",JiraDataset[[#This Row],[Summary]],"") -> Localization & Accessibility | AC30: =IF(JiraDataset[[#This Row],[RowType]]=cfg_type_skip,"",IFERROR(VLOOKUP(JiraDataset[[#This Row],[Sprint Name]], 'Config - Mappings'!$G$4:$H$8, 2, FALSE), "")) | AD30: =IF(JiraDataset[[#This Row],[RowType]]=cfg_type_skip,"",_xlfn.XLOOKUP("Creation Marker", CfgMisc[Name], CfgMisc[Value],"",1)) -> imported | AE30: =IF(JiraDataset[[#This Row],[RowType]]=cfg_type_skip,"",_xlfn.XLOOKUP("Work Group", CfgMisc[Name], CfgMisc[Value],"",1)) -> pod_test | AF30: =IF(JiraDataset[[#This Row],[RowType]]=cfg_type_skip,"",IFERROR(VLOOKUP(JiraDataset[[#This Row],[Assignee.Name]], 'Config - Mappings'!$A$4:$B$26, 2, FALSE), "")) -> 712020:09876543212345678903 | AG30: =IF(JiraDataset[[#This Row],[RowType]]=cfg_type_skip,"",_xlfn.XLOOKUP("jira.project.key", CfgBasic[Name], CfgBasic[Value])) -> JITTP2 | AH30: {=IF( JiraDataset[[#This Row],[RowType]]=cfg_type_skip, "", _xlfn.LET( _xlpm.p, _xlfn.TEXTSPLIT(JiraDataset[[#This Row],[Estimate]], " "), _xlpm.getVal, _xlfn.LAMBDA(_xlpm.u, IFERROR(VALUE(LEFT(_xlfn._xlws.FILTER(_xlpm.p, RIGHT(_xlpm.p,1)=_xlpm.u), LEN(_xlfn._xlws.FILTER(_xlpm.p, RIGHT(_xlpm.p,1)=_xlpm.u))-1)), 0)), _xlpm.w, _xlpm.getVal("w"), _xlpm.d, _xlpm.getVal("d"), _xlpm.h, _xlpm.getVal("h"), _xlpm.m, _xlpm.getVal("m"), _xlpm.seconds, _xlpm.w*144000 + _xlpm.d*28800 + _xlpm.h*3600 + _xlpm.m*60, IF(_xlpm.seconds=0, "", _xlpm.seconds*60) ) )} -> 8640000 | AI30: {=IFERROR( _xlfn.IFS( JiraDataset[[#This Row],[IssueType]] = cfg_type_comment,"SKIP", JiraDataset[[#This Row],[IssueType]] = cfg_type_skip,"SKIP", JiraDataset[[#This Row],[IssueType]] = cfg_type_note,"SKIP" ), cfg_type_workitem )} -> WorkItem
A31: Medium | B31: story | C31: Language Packs | E31: Ship EN/FR/DE language packs | F31: JITTP Version 1 | G31: Alice A | H31: Localization | J31: 3d | K31: 29 | L31: 28 | N31: =IF(JiraDataset[[#This Row],[IssueType]]="Epic",JiraDataset[[#This Row],[Summary]],"") | AC31: =IF(JiraDataset[[#This Row],[RowType]]=cfg_type_skip,"",IFERROR(VLOOKUP(JiraDataset[[#This Row],[Sprint Name]], 'Config - Mappings'!$G$4:$H$8, 2, FALSE), "")) | AD31: =IF(JiraDataset[[#This Row],[RowType]]=cfg_type_skip,"",_xlfn.XLOOKUP("Creation Marker", CfgMisc[Name], CfgMisc[Value],"",1)) -> imported | AE31: =IF(JiraDataset[[#This Row],[RowType]]=cfg_type_skip,"",_xlfn.XLOOKUP("Work Group", CfgMisc[Name], CfgMisc[Value],"",1)) -> pod_test | AF31: =IF(JiraDataset[[#This Row],[RowType]]=cfg_type_skip,"",IFERROR(VLOOKUP(JiraDataset[[#This Row],[Assignee.Name]], 'Config - Mappings'!$A$4:$B$26, 2, FALSE), "")) -> 712020:09876543212345678904 | AG31: =IF(JiraDataset[[#This Row],[RowType]]=cfg_type_skip,"",_xlfn.XLOOKUP("jira.project.key", CfgBasic[Name], CfgBasic[Value])) -> JITTP2 | AH31: {=IF( JiraDataset[[#This Row],[RowType]]=cfg_type_skip, "", _xlfn.LET( _xlpm.p, _xlfn.TEXTSPLIT(JiraDataset[[#This Row],[Estimate]], " "), _xlpm.getVal, _xlfn.LAMBDA(_xlpm.u, IFERROR(VALUE(LEFT(_xlfn._xlws.FILTER(_xlpm.p, RIGHT(_xlpm.p,1)=_xlpm.u), LEN(_xlfn._xlws.FILTER(_xlpm.p, RIGHT(_xlpm.p,1)=_xlpm.u))-1)), 0)), _xlpm.w, _xlpm.getVal("w"), _xlpm.d, _xlpm.getVal("d"), _xlpm.h, _xlpm.getVal("h"), _xlpm.m, _xlpm.getVal("m"), _xlpm.seconds, _xlpm.w*144000 + _xlpm.d*28800 + _xlpm.h*3600 + _xlpm.m*60, IF(_xlpm.seconds=0, "", _xlpm.seconds*60) ) )} -> 5184000 | AI31: {=IFERROR( _xlfn.IFS( JiraDataset[[#This Row],[IssueType]] = cfg_type_comment,"SKIP", JiraDataset[[#This Row],[IssueType]] = cfg_type_skip,"SKIP", JiraDataset[[#This Row],[IssueType]] = cfg_type_note,"SKIP" ), cfg_type_workitem )} -> WorkItem
... A42: Medium | B42: sub-task | C42: Charts: Load Tests | E42: Create performance tests for charts | F42: JITTP Version 1 | G42: Bob B | H42: Testing | J42: 1d | K42: 40 | L42: 39 | N42: =IF(JiraDataset[[#This Row],[IssueType]]="Epic",JiraDataset[[#This Row],[Summary]],"") | AC42: =IF(JiraDataset[[#This Row],[RowType]]=cfg_type_skip,"",IFERROR(VLOOKUP(JiraDataset[[#This Row],[Sprint Name]], 'Config - Mappings'!$G$4:$H$8, 2, FALSE), "")) | AD42: =IF(JiraDataset[[#This Row],[RowType]]=cfg_type_skip,"",_xlfn.XLOOKUP("Creation Marker", CfgMisc[Name], CfgMisc[Value],"",1)) -> imported | AE42: =IF(JiraDataset[[#This Row],[RowType]]=cfg_type_skip,"",_xlfn.XLOOKUP("Work Group", CfgMisc[Name], CfgMisc[Value],"",1)) -> pod_test | AF42: =IF(JiraDataset[[#This Row],[RowType]]=cfg_type_skip,"",IFERROR(VLOOKUP(JiraDataset[[#This Row],[Assignee.Name]], 'Config - Mappings'!$A$4:$B$26, 2, FALSE), "")) -> 712020:09876543212345678905 | AG42: =IF(JiraDataset[[#This Row],[RowType]]=cfg_type_skip,"",_xlfn.XLOOKUP("jira.project.key", CfgBasic[Name], CfgBasic[Value])) -> JITTP2 | AH42: {=IF( JiraDataset[[#This Row],[RowType]]=cfg_type_skip, "", _xlfn.LET( _xlpm.p, _xlfn.TEXTSPLIT(JiraDataset[[#This Row],[Estimate]], " "), _xlpm.getVal, _xlfn.LAMBDA(_xlpm.u, IFERROR(VALUE(LEFT(_xlfn._xlws.FILTER(_xlpm.p, RIGHT(_xlpm.p,1)=_xlpm.u), LEN(_xlfn._xlws.FILTER(_xlpm.p, RIGHT(_xlpm.p,1)=_xlpm.u))-1)), 0)), _xlpm.w, _xlpm.getVal("w"), _xlpm.d, _xlpm.getVal("d"), _xlpm.h, _xlpm.getVal("h"), _xlpm.m, _xlpm.getVal("m"), _xlpm.seconds, _xlpm.w*144000 + _xlpm.d*28800 + _xlpm.h*3600 + _xlpm.m*60, IF(_xlpm.seconds=0, "", _xlpm.seconds*60) ) )} -> 1728000 | AI42: {=IFERROR( _xlfn.IFS( JiraDataset[[#This Row],[IssueType]] = cfg_type_comment,"SKIP", JiraDataset[[#This Row],[IssueType]] = cfg_type_skip,"SKIP", JiraDataset[[#This Row],[IssueType]] = cfg_type_note,"SKIP" ), cfg_type_workitem )} -> WorkItem

Sheet Quick Analysis
A1: This sheet is ignored by the importer, it can contain anything
D3: FixVersion | E3: (All)
A4: FixVersion/Sprint/Type | D4: Type/Assignee
A5: Row Labels | B5: Count | D5: Row Labels | E5: Count
A6: (blank) | B6: 1 | D6: Epic | E6: 1
A7: (blank) | B7: 1 | D7: joe.grunt | E7: 1
A8: Note | B8: 1 | D8: Note | E8: 1
A9: JITTP Version 1 | B9: 1 | D9: (blank) | E9: 1
A10: JITTP_Sprint_48 | B10: 1 | D10: Grand Total | E10: 2
A11: Epic | B11: 1
A12: Grand Total | B12: 2

Sheet Help
A1: Notes
A2: Jira Toolkit: Importer 🚀 | C2: =_xlfn.CONCAT("Configuration version ", _xlfn.XLOOKUP("metadata.version", CfgSettings[Name], CfgSettings[Value])) -> Configuration version 8
A3: Documentation | C3: https://github.com/DeerHide/jira-toolkit/blob/main/README.md
A4: License | C4: MIT License
A5: Releases | C5: https://github.com/DeerHide/jira-toolkit/releases
A6: Sources | C6: https://github.com/DeerHide/jira-toolkit
A7: Author(s) | C7: https://deerhide.run
A9: FAQ | B9: 1 | C9: Why does the conditional formatting look off? (row formatting)
C10: In excel, moving, copying/pasting rows can break the conditional formatting. This can be fixed by using the format painter using the first row as reference.
B11: 2 | C11: All field from the Data Validation report #REF
C12: This can happen when the file gets exported from Gsheet. Best course of action is to redo an export to fix the table and range names.
A19: Configuration
A21: Name | B21: Type | C21: Description
A22: Config - Basic | B22: Sheet | C22: Everyday project settings used during import. Start here before the other config sheets.
A23: =HYPERLINK("#CfgBasic","CfgBasic") -> CfgBasic | B23: Table | C23: Basic key/value settings for the project (for example: project key, import labels, site address).
A24: Config - Mappings | B24: Sheet | C24: Reference lists that match spreadsheet values to valid Jira options.
A25: =HYPERLINK("#CfgAssignees", "CfgAssignees") -> CfgAssignees | B25: Table | C25: Maps friendly assignee names to Jira user IDs. DC installs use email addresses.
A26: =HYPERLINK("#CfgSprints","CfgSprints") -> CfgSprints | B26: Table | C26: Maps sprint names to Jira sprint IDs.
A27: =HYPERLINK("#CfgFixVersions","CfgFixVersions") -> CfgFixVersions | B27: Table | C27: Lists fix versions allowed in the import.
A28: =HYPERLINK("#CfgIssueTypes","CfgIssueTypes") -> CfgIssueTypes | B28: Table | C28: Lists issue types allowed in the import.
A29: =HYPERLINK("#CfgComponents","CfgComponents") -> CfgComponents | B29: Table | C29: Lists components allowed in the import.
A30: =HYPERLINK("#CfgPriorities","CfgPriorities") -> CfgPriorities | B30: Table | C30: Lists priorities allowed in the import.
A31: Config - Advanced | B31: Sheet | C31: Advanced settings, custom fields, and special import behavior. Also contains build-specific settings.
A32: =HYPERLINK("#CfgAdvanced","CfgAdvanced") -> CfgAdvanced | B32: Table | C32: Key/value settings for connection and import behavior.
A33: =HYPERLINK("#CfgCustomFields","CfgCustomFields") -> CfgCustomFields | B33: Table | C33: Defines custom Jira fields used by extra dataset columns.
A34: Config - Factory | B34: Sheet | C34: Auto-generated configuration area. Contains system tables and defaults—do not modify manually.
A35: =HYPERLINK("#CfgSettings","CfgSettings") -> CfgSettings | B35: Table | C35: Main app settings, such as config version and skip rules. Use columns Name and Value.
A36: =HYPERLINK("#CfgAutofieldValues","CfgAutofieldValues") -> CfgAutofieldValues | B36: Table | C36: Default values applied automatically when a field is empty. Use columns Name and Value.
A37: IssueType.Name | B37: List | C37: Generated dropdown source for the dataset. Combines allowed issue types and skip/note types from CfgIssueTypes + CfgIgnoreList.
A38: =HYPERLINK("#cfg_type_note","cfg_type_note") -> cfg_type_note | B38: Table | C38: Workbook helper name (not read by the app). Used for Excel formulas and validation.

Sheet Config - Basic
A1: Basic Configuration | E1: Misc Configuration
A2: Basic Configuration | E2: Parameters only used by the Template
A3: Name | B3: Value | C3: Note | E3: Name | F3: Value | G3: Note
